Workbook

Sheet Model
A1: Bear River Basin Water Bank
B2: Partipants instructions are given bold blue text
A4: 1 | B4: Assign participants and define water use strategy. Cell C6 to D13
A5: Party | C5: Person | D5: Strategy
A6: TIER | B6: WATER USERS INCLUDED
A7: A | B7: Upper and Central Division
A8: B | B8: Lower ID
A9: C | B9: Lower UT - BRC
A10: D | B10: Lower UT- BirdRefuge
A11: E | B11: Bank
A13: 2 | B13: Reservoir Assumptions | C13: Cutler | D13: Bear Lake | E13: Onieda | F13: Alexendar | G13: Total
B14: Maximum Reservoir Storage (acre-feet) | G14: =SUM(C14:D14) -> 0
B15: Reservoir Max elvation (feet)
B16: Protect elevation (feet)
B17: Storage at protection elevation (af) | G17: =SUM(C17:D17) -> 0
B18: Maximum Reservoir Active Storage | G18: =SUM(C18:D18) -> 0
B19: Evaporation rate (feet/year)
A21: 3 | B21: Water Budget (acft) | C21: Year 1 | D21: Year 2 | E21: Year 3 | F21: Year 4
B22: Beginning of the year reservoir elevation (ft)
D23: =C106 -> #N/A | E23: =D106 -> #N/A | F23: =E106 -> #N/A
D26: =C107 -> #N/A | E26: =D107 -> #N/A | F26: =E107 -> #N/A
A27: 3A | B27: Beginning of the year reservoir storage (acft)
C28: =VLOOKUP(C$23,'[1]Elevation-Area-Storage'!$A$5:$C$735,3) -> #N/A | D28: =VLOOKUP(D$23,'[1]Elevation-Area-Storage'!$A$5:$C$735,3) -> #N/A | E28: =VLOOKUP(E$23,'[1]Elevation-Area-Storage'!$A$5:$C$735,3) -> #N/A | F28: =VLOOKUP(F$23,'[1]Elevation-Area-Storage'!$A$5:$C$735,3) -> #N/A
C29: =VLOOKUP(C$26,'[1]Elevation-Area-Storage'!$D$5:$F$152,3) -> #N/A | D29: =VLOOKUP(D$26,'[1]Elevation-Area-Storage'!$D$5:$F$152,3) -> #N/A | E29: =VLOOKUP(E$26,'[1]Elevation-Area-Storage'!$D$5:$F$152,3) -> #N/A | F29: =VLOOKUP(F$26,'[1]Elevation-Area-Storage'!$D$5:$F$152,3) -> #N/A
B30: Total Start Storage for the System(acft) | C30: =SUM(C28:C29) -> #N/A | D30: =SUM(D28:D29) -> #N/A | E30: =SUM(E28:E29) -> #N/A | F30: =SUM(F28:F29) -> #N/A
B31: Total Active Storage (acft) | C31: =SUM(C28:C29)-$G$17 -> #N/A | D31: =SUM(D28:D29)-$G$17 -> #N/A | E31: =SUM(E28:E29)-$G$17 -> #N/A | F31: =SUM(F28:F29)-$G$17 -> #N/A
B32: Total Evaporation from Reservoirs(acft) | C32: =((VLOOKUP(C$23,'[1]Elevation-Area-Storage'!$A$5:$C$735,2))+(VLOOKUP(C$26,'[1]Elevation-Area-Storage'!$D$5:$F$152,2)))*$C$19 -> #N/A | D32: =((VLOOKUP(D$23,'[1]Elevation-Area-Storage'!$A$5:$C$735,2))+(VLOOKUP(D$26,'[1]Elevation-Area-Storage'!$D$5:$F$152,2)))*$C$19 -> #N/A | E32: =((VLOOKUP(E$23,'[1]Elevation-Area-Storage'!$A$5:$C$735,2))+(VLOOKUP(E$26,'[1]Elevation-Area-Storage'!$D$5:$F$152,2)))*$C$19 -> #N/A | F32: =((VLOOKUP(F$23,'[1]Elevation-Area-Storage'!$A$5:$C$735,2))+(VLOOKUP(F$26,'[1]Elevation-Area-Storage'!$D$5:$F$152,2)))*$C$19 -> #N/A
A33: 3B | B33: Select percentile of flow as compared to historic flows (Choose 1 - 99) [acft]. | C33: 50 | D33: 0 | E33: 0 | F33: 0
B34: Winter Flow (October - March) - acft
B35: Upper | C35: {=IF(C$33 < 1, _xlfn.XLOOKUP($B35,'[1]Inflow Quantiles - Seasonal'!$A$34:$A$38,'[1]Inflow Quantiles - Seasonal'!$B$34:$B$38)*C$33, IF(C$33 > 100,_xlfn.XLOOKUP($B35,'[1]Inflow Quantiles - Seasonal'!$A$34:$A$38,'[1]Inflow Quantiles - Seasonal'!$CW$34:$CW$38)*C$33/100, _xlfn.XLOOKUP(C$33,'[1]Inflow Quantiles - Seasonal'!$B$33:$CW$33, _xlfn.XLOOKUP($B35,'[1]Inflow Quantiles - Seasonal'!$A$34:$A$38,'[1]Inflow Quantiles - Seasonal'!$B$34:$CW$38))))*1000} -> #N/A | D35: {=IF(D$33 < 1, _xlfn.XLOOKUP($B35,'[1]Inflow Quantiles - Seasonal'!$A$34:$A$38,'[1]Inflow Quantiles - Seasonal'!$B$34:$B$38)*D$33, IF(D$33 > 100,_xlfn.XLOOKUP($B35,'[1]Inflow Quantiles - Seasonal'!$A$34:$A$38,'[1]Inflow Quantiles - Seasonal'!$CW$34:$CW$38)*D$33/100, _xlfn.XLOOKUP(D$33,'[1]Inflow Quantiles - Seasonal'!$B$33:$CW$33, _xlfn.XLOOKUP($B35,'[1]Inflow Quantiles - Seasonal'!$A$34:$A$38,'[1]Inflow Quantiles - Seasonal'!$B$34:$CW$38))))*1000} -> #N/A | E35: {=IF(E$33 < 1, _xludf.XLOOKUP($B35,'[1]Inflow Quantiles - Seasonal'!$A$34:$A$38,'[1]Inflow Quantiles - Seasonal'!$B$34:$B$38)*E$33, IF(E$33 > 100,_xludf.XLOOKUP($B35,'[1]Inflow Quantiles - Seasonal'!$A$34:$A$38,'[1]Inflow Quantiles - Seasonal'!$CW$34:$CW$38)*E$33/100, _xludf.XLOOKUP(E$33,'[1]Inflow Quantiles - Seasonal'!$B$33:$CW$33, _xludf.XLOOKUP($B35,'[1]Inflow Quantiles - Seasonal'!$A$34:$A$38,'[1]Inflow Quantiles - Seasonal'!$B$34:$CW$38))))*1000} -> #NAME? | F35: {=IF(F$33 < 1, _xludf.XLOOKUP($B35,'[1]Inflow Quantiles - Seasonal'!$A$34:$A$38,'[1]Inflow Quantiles - Seasonal'!$B$34:$B$38)*F$33, IF(F$33 > 100,_xludf.XLOOKUP($B35,'[1]Inflow Quantiles - Seasonal'!$A$34:$A$38,'[1]Inflow Quantiles - Seasonal'!$CW$34:$CW$38)*F$33/100, _xludf.XLOOKUP(F$33,'[1]Inflow Quantiles - Seasonal'!$B$33:$CW$33, _xludf.XLOOKUP($B35,'[1]Inflow Quantiles - Seasonal'!$A$34:$A$38,'[1]Inflow Quantiles - Seasonal'!$B$34:$CW$38))))*1000} -> #NAME?
C36: {=IF(C$33 < 1, _xlfn.XLOOKUP($B36,'[1]Inflow Quantiles - Seasonal'!$A$34:$A$38,'[1]Inflow Quantiles - Seasonal'!$B$34:$B$38)*C$33, IF(C$33 > 100,_xlfn.XLOOKUP($B36,'[1]Inflow Quantiles - Seasonal'!$A$34:$A$38,'[1]Inflow Quantiles - Seasonal'!$CW$34:$CW$38)*C$33/100, _xlfn.XLOOKUP(C$33,'[1]Inflow Quantiles - Seasonal'!$B$33:$CW$33, _xlfn.XLOOKUP($B36,'[1]Inflow Quantiles - Seasonal'!$A$34:$A$38,'[1]Inflow Quantiles - Seasonal'!$B$34:$CW$38))))*1000} -> #N/A | D36: {=IF(D$33 < 1, _xlfn.XLOOKUP($B36,'[1]Inflow Quantiles - Seasonal'!$A$34:$A$38,'[1]Inflow Quantiles - Seasonal'!$B$34:$B$38)*D$33, IF(D$33 > 100,_xlfn.XLOOKUP($B36,'[1]Inflow Quantiles - Seasonal'!$A$34:$A$38,'[1]Inflow Quantiles - Seasonal'!$CW$34:$CW$38)*D$33/100, _xlfn.XLOOKUP(D$33,'[1]Inflow Quantiles - Seasonal'!$B$33:$CW$33, _xlfn.XLOOKUP($B36,'[1]Inflow Quantiles - Seasonal'!$A$34:$A$38,'[1]Inflow Quantiles - Seasonal'!$B$34:$CW$38))))*1000} -> #N/A | E36: {=IF(E$33 < 1, _xludf.XLOOKUP($B36,'[1]Inflow Quantiles - Seasonal'!$A$34:$A$38,'[1]Inflow Quantiles - Seasonal'!$B$34:$B$38)*E$33, IF(E$33 > 100,_xludf.XLOOKUP($B36,'[1]Inflow Quantiles - Seasonal'!$A$34:$A$38,'[1]Inflow Quantiles - Seasonal'!$CW$34:$CW$38)*E$33/100, _xludf.XLOOKUP(E$33,'[1]Inflow Quantiles - Seasonal'!$B$33:$CW$33, _xludf.XLOOKUP($B36,'[1]Inflow Quantiles - Seasonal'!$A$34:$A$38,'[1]Inflow Quantiles - Seasonal'!$B$34:$CW$38))))*1000} -> #NAME? | F36: {=IF(F$33 < 1, _xludf.XLOOKUP($B36,'[1]Inflow Quantiles - Seasonal'!$A$34:$A$38,'[1]Inflow Quantiles - Seasonal'!$B$34:$B$38)*F$33, IF(F$33 > 100,_xludf.XLOOKUP($B36,'[1]Inflow Quantiles - Seasonal'!$A$34:$A$38,'[1]Inflow Quantiles - Seasonal'!$CW$34:$CW$38)*F$33/100, _xludf.XLOOKUP(F$33,'[1]Inflow Quantiles - Seasonal'!$B$33:$CW$33, _xludf.XLOOKUP($B36,'[1]Inflow Quantiles - Seasonal'!$A$34:$A$38,'[1]Inflow Quantiles - Seasonal'!$B$34:$CW$38))))*1000} -> #NAME?
C37: {=IF(C$33 < 1, _xlfn.XLOOKUP($B37,'[1]Inflow Quantiles - Seasonal'!$A$34:$A$38,'[1]Inflow Quantiles - Seasonal'!$B$34:$B$38)*C$33, IF(C$33 > 100,_xlfn.XLOOKUP($B37,'[1]Inflow Quantiles - Seasonal'!$A$34:$A$38,'[1]Inflow Quantiles - Seasonal'!$CW$34:$CW$38)*C$33/100, _xlfn.XLOOKUP(C$33,'[1]Inflow Quantiles - Seasonal'!$B$33:$CW$33, _xlfn.XLOOKUP($B37,'[1]Inflow Quantiles - Seasonal'!$A$34:$A$38,'[1]Inflow Quantiles - Seasonal'!$B$34:$CW$38))))*1000} -> #N/A | D37: {=IF(D$33 < 1, _xludf.XLOOKUP($B37,'[1]Inflow Quantiles - Seasonal'!$A$34:$A$38,'[1]Inflow Quantiles - Seasonal'!$B$34:$B$38)*D$33, IF(D$33 > 100,_xludf.XLOOKUP($B37,'[1]Inflow Quantiles - Seasonal'!$A$34:$A$38,'[1]Inflow Quantiles - Seasonal'!$CW$34:$CW$38)*D$33/100, _xludf.XLOOKUP(D$33,'[1]Inflow Quantiles - Seasonal'!$B$33:$CW$33, _xludf.XLOOKUP($B37,'[1]Inflow Quantiles - Seasonal'!$A$34:$A$38,'[1]Inflow Quantiles - Seasonal'!$B$34:$CW$38))))*1000} -> #NAME? | E37: {=IF(E$33 < 1, _xludf.XLOOKUP($B37,'[1]Inflow Quantiles - Seasonal'!$A$34:$A$38,'[1]Inflow Quantiles - Seasonal'!$B$34:$B$38)*E$33, IF(E$33 > 100,_xludf.XLOOKUP($B37,'[1]Inflow Quantiles - Seasonal'!$A$34:$A$38,'[1]Inflow Quantiles - Seasonal'!$CW$34:$CW$38)*E$33/100, _xludf.XLOOKUP(E$33,'[1]Inflow Quantiles - Seasonal'!$B$33:$CW$33, _xludf.XLOOKUP($B37,'[1]Inflow Quantiles - Seasonal'!$A$34:$A$38,'[1]Inflow Quantiles - Seasonal'!$B$34:$CW$38))))*1000} -> #NAME? | F37: {=IF(F$33 < 1, _xludf.XLOOKUP($B37,'[1]Inflow Quantiles - Seasonal'!$A$34:$A$38,'[1]Inflow Quantiles - Seasonal'!$B$34:$B$38)*F$33, IF(F$33 > 100,_xludf.XLOOKUP($B37,'[1]Inflow Quantiles - Seasonal'!$A$34:$A$38,'[1]Inflow Quantiles - Seasonal'!$CW$34:$CW$38)*F$33/100, _xludf.XLOOKUP(F$33,'[1]Inflow Quantiles - Seasonal'!$B$33:$CW$33, _xludf.XLOOKUP($B37,'[1]Inflow Quantiles - Seasonal'!$A$34:$A$38,'[1]Inflow Quantiles - Seasonal'!$B$34:$CW$38))))*1000} -> #NAME?
C38: {=IF(C$33 < 1, _xlfn.XLOOKUP($B38,'[1]Inflow Quantiles - Seasonal'!$A$34:$A$38,'[1]Inflow Quantiles - Seasonal'!$B$34:$B$38)*C$33, IF(C$33 > 100,_xlfn.XLOOKUP($B38,'[1]Inflow Quantiles - Seasonal'!$A$34:$A$38,'[1]Inflow Quantiles - Seasonal'!$CW$34:$CW$38)*C$33/100, _xlfn.XLOOKUP(C$33,'[1]Inflow Quantiles - Seasonal'!$B$33:$CW$33, _xlfn.XLOOKUP($B38,'[1]Inflow Quantiles - Seasonal'!$A$34:$A$38,'[1]Inflow Quantiles - Seasonal'!$B$34:$CW$38))))*1000} -> #N/A | D38: {=IF(D$33 < 1, _xludf.XLOOKUP($B38,'[1]Inflow Quantiles - Seasonal'!$A$34:$A$38,'[1]Inflow Quantiles - Seasonal'!$B$34:$B$38)*D$33, IF(D$33 > 100,_xludf.XLOOKUP($B38,'[1]Inflow Quantiles - Seasonal'!$A$34:$A$38,'[1]Inflow Quantiles - Seasonal'!$CW$34:$CW$38)*D$33/100, _xludf.XLOOKUP(D$33,'[1]Inflow Quantiles - Seasonal'!$B$33:$CW$33, _xludf.XLOOKUP($B38,'[1]Inflow Quantiles - Seasonal'!$A$34:$A$38,'[1]Inflow Quantiles - Seasonal'!$B$34:$CW$38))))*1000} -> #NAME? | E38: {=IF(E$33 < 1, _xludf.XLOOKUP($B38,'[1]Inflow Quantiles - Seasonal'!$A$34:$A$38,'[1]Inflow Quantiles - Seasonal'!$B$34:$B$38)*E$33, IF(E$33 > 100,_xludf.XLOOKUP($B38,'[1]Inflow Quantiles - Seasonal'!$A$34:$A$38,'[1]Inflow Quantiles - Seasonal'!$CW$34:$CW$38)*E$33/100, _xludf.XLOOKUP(E$33,'[1]Inflow Quantiles - Seasonal'!$B$33:$CW$33, _xludf.XLOOKUP($B38,'[1]Inflow Quantiles - Seasonal'!$A$34:$A$38,'[1]Inflow Quantiles - Seasonal'!$B$34:$CW$38))))*1000} -> #NAME? | F38: {=IF(F$33 < 1, _xludf.XLOOKUP($B38,'[1]Inflow Quantiles - Seasonal'!$A$34:$A$38,'[1]Inflow Quantiles - Seasonal'!$B$34:$B$38)*F$33, IF(F$33 > 100,_xludf.XLOOKUP($B38,'[1]Inflow Quantiles - Seasonal'!$A$34:$A$38,'[1]Inflow Quantiles - Seasonal'!$CW$34:$CW$38)*F$33/100, _xludf.XLOOKUP(F$33,'[1]Inflow Quantiles - Seasonal'!$B$33:$CW$33, _xludf.XLOOKUP($B38,'[1]Inflow Quantiles - Seasonal'!$A$34:$A$38,'[1]Inflow Quantiles - Seasonal'!$B$34:$CW$38))))*1000} -> #NAME?
C39: =SUM(C35:C38) -> #N/A | D39: =SUM(D35:D38) -> #N/A | E39: =SUM(E35:E38) -> #NAME? | F39: =SUM(F35:F38) -> #NAME?
B40: Summer Flow (April - September) - acft
C41: {=IF(C$33<1,_xlfn.XLOOKUP($B41,'[1]Inflow Quantiles - Seasonal'!$A$26:$A$29,'[1]Inflow Quantiles - Seasonal'!$B$26:$B$29)*C$33,IF($C$33>100,_xlfn.XLOOKUP($B41,'[1]Inflow Quantiles - Seasonal'!$A$26:$A$29,'[1]Inflow Quantiles - Seasonal'!$CW$26:$CW$29)*C$33/100,_xlfn.XLOOKUP(C$33,'[1]Inflow Quantiles - Seasonal'!$B$25:$CW$25,_xlfn.XLOOKUP(Model!$B41,'[1]Inflow Quantiles - Seasonal'!$A$26:$A$29,'[1]Inflow Quantiles - Seasonal'!$B$26:$CW$29))))*1000} -> #N/A | D41: {=IF(D$33<1,_xludf.XLOOKUP($B41,'[1]Inflow Quantiles - Seasonal'!$A$26:$A$29,'[1]Inflow Quantiles - Seasonal'!$B$26:$B$29)*D$33,IF($C$33>100,_xludf.XLOOKUP($B41,'[1]Inflow Quantiles - Seasonal'!$A$26:$A$29,'[1]Inflow Quantiles - Seasonal'!$CW$26:$CW$29)*D$33/100,_xludf.XLOOKUP(D$33,'[1]Inflow Quantiles - Seasonal'!$B$25:$CW$25,_xludf.XLOOKUP(Model!$B41,'[1]Inflow Quantiles - Seasonal'!$A$26:$A$29,'[1]Inflow Quantiles - Seasonal'!$B$26:$CW$29))))*1000} -> #NAME? | E41: {=IF(E$33<1,_xludf.XLOOKUP($B41,'[1]Inflow Quantiles - Seasonal'!$A$26:$A$29,'[1]Inflow Quantiles - Seasonal'!$B$26:$B$29)*E$33,IF($C$33>100,_xludf.XLOOKUP($B41,'[1]Inflow Quantiles - Seasonal'!$A$26:$A$29,'[1]Inflow Quantiles - Seasonal'!$CW$26:$CW$29)*E$33/100,_xludf.XLOOKUP(E$33,'[1]Inflow Quantiles - Seasonal'!$B$25:$CW$25,_xludf.XLOOKUP(Model!$B41,'[1]Inflow Quantiles - Seasonal'!$A$26:$A$29,'[1]Inflow Quantiles - Seasonal'!$B$26:$CW$29))))*1000} -> #NAME? | F41: {=IF(F$33<1,_xludf.XLOOKUP($B41,'[1]Inflow Quantiles - Seasonal'!$A$26:$A$29,'[1]Inflow Quantiles - Seasonal'!$B$26:$B$29)*F$33,IF($C$33>100,_xludf.XLOOKUP($B41,'[1]Inflow Quantiles - Seasonal'!$A$26:$A$29,'[1]Inflow Quantiles - Seasonal'!$CW$26:$CW$29)*F$33/100,_xludf.XLOOKUP(F$33,'[1]Inflow Quantiles - Seasonal'!$B$25:$CW$25,_xludf.XLOOKUP(Model!$B41,'[1]Inflow Quantiles - Seasonal'!$A$26:$A$29,'[1]Inflow Quantiles - Seasonal'!$B$26:$CW$29))))*1000} -> #NAME?
C42: {=IF(C$33<1,_xlfn.XLOOKUP($B42,'[2]Inflow Quantiles - Seasonal'!$A$26:$A$29,'[1]Inflow Quantiles - Seasonal'!$B$26:$B$29)*C$33,IF($C$33>100,_xlfn.XLOOKUP($B42,'[1]Inflow Quantiles - Seasonal'!$A$26:$A$29,'[1]Inflow Quantiles - Seasonal'!$CW$26:$CW$29)*C$33/100,_xlfn.XLOOKUP(C$33,'[1]Inflow Quantiles - Seasonal'!$B$25:$CW$25,_xlfn.XLOOKUP(Model!$B42,'[1]Inflow Quantiles - Seasonal'!$A$26:$A$29,'[1]Inflow Quantiles - Seasonal'!$B$26:$CW$29))))*1000} -> #N/A | D42: {=IF(D$33<1,_xludf.XLOOKUP($B42,'[1]Inflow Quantiles - Seasonal'!$A$26:$A$29,'[1]Inflow Quantiles - Seasonal'!$B$26:$B$29)*D$33,IF($C$33>100,_xludf.XLOOKUP($B42,'[1]Inflow Quantiles - Seasonal'!$A$26:$A$29,'[1]Inflow Quantiles - Seasonal'!$CW$26:$CW$29)*D$33/100,_xludf.XLOOKUP(D$33,'[1]Inflow Quantiles - Seasonal'!$B$25:$CW$25,_xludf.XLOOKUP(Model!$B42,'[1]Inflow Quantiles - Seasonal'!$A$26:$A$29,'[1]Inflow Quantiles - Seasonal'!$B$26:$CW$29))))*1000} -> #NAME? | E42: {=IF(E$33<1,_xludf.XLOOKUP($B42,'[1]Inflow Quantiles - Seasonal'!$A$26:$A$29,'[1]Inflow Quantiles - Seasonal'!$B$26:$B$29)*E$33,IF($C$33>100,_xludf.XLOOKUP($B42,'[1]Inflow Quantiles - Seasonal'!$A$26:$A$29,'[1]Inflow Quantiles - Seasonal'!$CW$26:$CW$29)*E$33/100,_xludf.XLOOKUP(E$33,'[1]Inflow Quantiles - Seasonal'!$B$25:$CW$25,_xludf.XLOOKUP(Model!$B42,'[1]Inflow Quantiles - Seasonal'!$A$26:$A$29,'[1]Inflow Quantiles - Seasonal'!$B$26:$CW$29))))*1000} -> #NAME? | F42: {=IF(F$33<1,_xludf.XLOOKUP($B42,'[1]Inflow Quantiles - Seasonal'!$A$26:$A$29,'[1]Inflow Quantiles - Seasonal'!$B$26:$B$29)*F$33,IF($C$33>100,_xludf.XLOOKUP($B42,'[1]Inflow Quantiles - Seasonal'!$A$26:$A$29,'[1]Inflow Quantiles - Seasonal'!$CW$26:$CW$29)*F$33/100,_xludf.XLOOKUP(F$33,'[1]Inflow Quantiles - Seasonal'!$B$25:$CW$25,_xludf.XLOOKUP(Model!$B42,'[1]Inflow Quantiles - Seasonal'!$A$26:$A$29,'[1]Inflow Quantiles - Seasonal'!$B$26:$CW$29))))*1000} -> #NAME?
C43: {=IF(C$33<1,_xlfn.XLOOKUP($B43,'[1]Inflow Quantiles - Seasonal'!$A$26:$A$29,'[1]Inflow Quantiles - Seasonal'!$B$26:$B$29)*C$33,IF($C$33>100,_xlfn.XLOOKUP($B43,'[1]Inflow Quantiles - Seasonal'!$A$26:$A$29,'[1]Inflow Quantiles - Seasonal'!$CW$26:$CW$29)*C$33/100,_xlfn.XLOOKUP(C$33,'[1]Inflow Quantiles - Seasonal'!$B$25:$CW$25,_xlfn.XLOOKUP(Model!$B43,'[1]Inflow Quantiles - Seasonal'!$A$26:$A$29,'[1]Inflow Quantiles - Seasonal'!$B$26:$CW$29))))*1000} -> #N/A | D43: {=IF(D$33<1,_xludf.XLOOKUP($B43,'[1]Inflow Quantiles - Seasonal'!$A$26:$A$29,'[1]Inflow Quantiles - Seasonal'!$B$26:$B$29)*D$33,IF($C$33>100,_xludf.XLOOKUP($B43,'[1]Inflow Quantiles - Seasonal'!$A$26:$A$29,'[1]Inflow Quantiles - Seasonal'!$CW$26:$CW$29)*D$33/100,_xludf.XLOOKUP(D$33,'[1]Inflow Quantiles - Seasonal'!$B$25:$CW$25,_xludf.XLOOKUP(Model!$B43,'[1]Inflow Quantiles - Seasonal'!$A$26:$A$29,'[1]Inflow Quantiles - Seasonal'!$B$26:$CW$29))))*1000} -> #NAME? | E43: {=IF(E$33<1,_xludf.XLOOKUP($B43,'[1]Inflow Quantiles - Seasonal'!$A$26:$A$29,'[1]Inflow Quantiles - Seasonal'!$B$26:$B$29)*E$33,IF($C$33>100,_xludf.XLOOKUP($B43,'[1]Inflow Quantiles - Seasonal'!$A$26:$A$29,'[1]Inflow Quantiles - Seasonal'!$CW$26:$CW$29)*E$33/100,_xludf.XLOOKUP(E$33,'[1]Inflow Quantiles - Seasonal'!$B$25:$CW$25,_xludf.XLOOKUP(Model!$B43,'[1]Inflow Quantiles - Seasonal'!$A$26:$A$29,'[1]Inflow Quantiles - Seasonal'!$B$26:$CW$29))))*1000} -> #NAME? | F43: {=IF(F$33<1,_xludf.XLOOKUP($B43,'[1]Inflow Quantiles - Seasonal'!$A$26:$A$29,'[1]Inflow Quantiles - Seasonal'!$B$26:$B$29)*F$33,IF($C$33>100,_xludf.XLOOKUP($B43,'[1]Inflow Quantiles - Seasonal'!$A$26:$A$29,'[1]Inflow Quantiles - Seasonal'!$CW$26:$CW$29)*F$33/100,_xludf.XLOOKUP(F$33,'[1]Inflow Quantiles - Seasonal'!$B$25:$CW$25,_xludf.XLOOKUP(Model!$B43,'[1]Inflow Quantiles - Seasonal'!$A$26:$A$29,'[1]Inflow Quantiles - Seasonal'!$B$26:$CW$29))))*1000} -> #NAME?
C44: {=IF(C$33<1,_xlfn.XLOOKUP($B44,'[1]Inflow Quantiles - Seasonal'!$A$26:$A$29,'[1]Inflow Quantiles - Seasonal'!$B$26:$B$29)*C$33,IF($C$33>100,_xlfn.XLOOKUP($B44,'[1]Inflow Quantiles - Seasonal'!$A$26:$A$29,'[1]Inflow Quantiles - Seasonal'!$CW$26:$CW$29)*C$33/100,_xlfn.XLOOKUP(C$33,'[1]Inflow Quantiles - Seasonal'!$B$25:$CW$25,_xlfn.XLOOKUP(Model!$B44,'[1]Inflow Quantiles - Seasonal'!$A$26:$A$29,'[1]Inflow Quantiles - Seasonal'!$B$26:$CW$29))))*1000} -> #N/A | D44: {=IF(D$33<1,_xludf.XLOOKUP($B44,'[1]Inflow Quantiles - Seasonal'!$A$26:$A$29,'[1]Inflow Quantiles - Seasonal'!$B$26:$B$29)*D$33,IF($C$33>100,_xludf.XLOOKUP($B44,'[1]Inflow Quantiles - Seasonal'!$A$26:$A$29,'[1]Inflow Quantiles - Seasonal'!$CW$26:$CW$29)*D$33/100,_xludf.XLOOKUP(D$33,'[1]Inflow Quantiles - Seasonal'!$B$25:$CW$25,_xludf.XLOOKUP(Model!$B44,'[1]Inflow Quantiles - Seasonal'!$A$26:$A$29,'[1]Inflow Quantiles - Seasonal'!$B$26:$CW$29))))*1000} -> #NAME? | E44: {=IF(E$33<1,_xludf.XLOOKUP($B44,'[1]Inflow Quantiles - Seasonal'!$A$26:$A$29,'[1]Inflow Quantiles - Seasonal'!$B$26:$B$29)*E$33,IF($C$33>100,_xludf.XLOOKUP($B44,'[1]Inflow Quantiles - Seasonal'!$A$26:$A$29,'[1]Inflow Quantiles - Seasonal'!$CW$26:$CW$29)*E$33/100,_xludf.XLOOKUP(E$33,'[1]Inflow Quantiles - Seasonal'!$B$25:$CW$25,_xludf.XLOOKUP(Model!$B44,'[1]Inflow Quantiles - Seasonal'!$A$26:$A$29,'[1]Inflow Quantiles - Seasonal'!$B$26:$CW$29))))*1000} -> #NAME? | F44: {=IF(F$33<1,_xludf.XLOOKUP($B44,'[1]Inflow Quantiles - Seasonal'!$A$26:$A$29,'[1]Inflow Quantiles - Seasonal'!$B$26:$B$29)*F$33,IF($C$33>100,_xludf.XLOOKUP($B44,'[1]Inflow Quantiles - Seasonal'!$A$26:$A$29,'[1]Inflow Quantiles - Seasonal'!$CW$26:$CW$29)*F$33/100,_xludf.XLOOKUP(F$33,'[1]Inflow Quantiles - Seasonal'!$B$25:$CW$25,_xludf.XLOOKUP(Model!$B44,'[1]Inflow Quantiles - Seasonal'!$A$26:$A$29,'[1]Inflow Quantiles - Seasonal'!$B$26:$CW$29))))*1000} -> #NAME?
C45: =SUM(C41:C44) -> #N/A | D45: =SUM(D41:D44) -> #NAME? | E45: =SUM(E41:E44) -> #NAME? | F45: =SUM(F41:F44) -> #NAME?
...

Sheet Network
A1: Source | B1: http://www.bearriverbasin.org/rivers/rivers/

Sheet Diversions

Sheet Inflow Quantiles - Seasonal
A25: Summer | B25: 1 | C25: 2 | D25: 3 | E25: 4 | F25: 5 | G25: 6 | H25: 7 | I25: 8 | J25: 9 | K25: 10 | L25: 11 | M25: 12 | N25: 13 | O25: 14 | P25: 15 | Q25: 16 | R25: 17 | S25: 18 | T25: 19 | U25: 20 | V25: 21 | W25: 22 | X25: 23 | Y25: 24 | Z25: 25 | AA25: 26 | AB25: 27 | AC25: 28 | AD25: 29 | AE25: 30 | AF25: 31 | AG25: 32 | AH25: 33 | AI25: 34 | AJ25: 35 | AK25: 36 | AL25: 37 | AM25: 38 | AN25: 39 | AO25: 40 | AP25: 41 | AQ25: 42 | AR25: 43 | AS25: 44 | AT25: 45 | AU25: 46 | AV25: 47 | AW25: 48 | AX25: 49 | AY25: 50 | AZ25: 51 | BA25: 52 | BB25: 53 | BC25: 54 | BD25: 55 | BE25: 56 | BF25: 57 | BG25: 58 | BH25: 59 | BI25: 60 | BJ25: 61 | BK25: 62 | BL25: 63 | BM25: 64 | BN25: 65 | BO25: 66 | BP25: 67 | BQ25: 68 | BR25: 69 | BS25: 70 | BT25: 71 | BU25: 72 | BV25: 73 | BW25: 74 | BX25: 75 | BY25: 76 | BZ25: 77 | CA25: 78 | CB25: 79 | CC25: 80 | CD25: 81 | CE25: 82 | CF25: 83 | CG25: 84 | CH25: 85 | CI25: 86 | CJ25: 87 | CK25: 88 | CL25: 89 | CM25: 90 | CN25: 91 | CO25: 92 | CP25: 93 | CQ25: 94 | CR25: 95 | CS25: 96 | CT25: 97 | CU25: 98 | CV25: 99 | CW25: 100
A26: AboveWoodruff | B26: 32.17184 | C26: 32.788399 | D26: 33.404959 | E26: 34.021518 | F26: 34.522221 | G26: 35.022923 | H26: 35.523626 | I26: 36.024328 | J26: 39.056048 | K26: 42.087767 | L26: 45.119487 | M26: 48.151206 | N26: 48.516147 | O26: 48.881089 | P26: 49.24603 | Q26: 49.610972 | R26: 49.83984 | S26: 50.068708 | T26: 50.297575 | U26: 50.526443 | V26: 51.326609 | W26: 52.126774 | X26: 52.926939 | Y26: 53.727105 | Z26: 53.868552 | AA26: 54.009999 | AB26: 54.151447 | AC26: 54.292894 | AD26: 55.97887 | AE26: 57.664847 | AF26: 59.350823 | AG26: 61.036799 | AH26: 61.587315 | AI26: 62.13783 | AJ26: 62.688346 | AK26: 63.238861 | AL26: 64.512344 | AM26: 65.785827 | AN26: 67.059309 | AO26: 68.332792 | AP26: 70.545443 | AQ26: 72.758094 | AR26: 74.970746 | AS26: 77.183397 | AT26: 78.362489 | AU26: 79.54158 | AV26: 80.720672 | AW26: 81.899764 | AX26: 85.609942 | AY26: 89.32012 | AZ26: 93.030298 | BA26: 96.740477 | BB26: 97.776837 | BC26: 98.813197 | BD26: 99.849558 | BE26: 100.88592 | BF26: 104.49204 | BG26: 108.09817 | BH26: 111.70429 | BI26: 115.31042 | BJ26: 118.19371 | BK26: 121.077 | BL26: 123.96029 | BM26: 126.84359 | BN26: 127.72441 | BO26: 128.60523 | BP26: 129.48606 | BQ26: 130.36688 | BR26: 131.39798 | BS26: 132.42907 | BT26: 133.46017 | BU26: 134.49126 | BV26: 135.17648 | BW26: 135.8617 | BX26: 136.54691 | BY26: 137.23213 | BZ26: 138.6678 | CA26: 140.10348 | CB26: 141.53916 | CC26: 142.97484 | CD26: 145.52947 | CE26: 148.08411 | CF26: 150.63875 | CG26: 153.19339 | CH26: 156.7121 | CI26: 160.23081 | CJ26: 163.74952 | CK26: 167.26823 | CL26: 168.19313 | CM26: 169.11802 | CN26: 170.04292 | CO26: 170.96782 | CP26: 182.5605 | CQ26: 194.15318 | CR26: 205.74586 | CS26: 217.33855 | CT26: 249.41784 | CU26: 281.49714 | CV26: 313.57644 | CW26: 345.65574
A27: BelowPixley_Cokeville | B27: 1.8200172 | C27: 2.2272263 | D27: 2.6344353 | E27: 3.0416444 | F27: 3.2852113 | G27: 3.5287782 | H27: 3.7723452 | I27: 4.0159121 | J27: 4.0575055 | K27: 4.099099 | L27: 4.1406924 | M27: 4.1822858 | N27: 4.3198069 | O27: 4.4573279 | P27: 4.594849 | Q27: 4.73237 | R27: 5.800037 | S27: 6.8677041 | T27: 7.9353711 | U27: 9.0030381 | V27: 10.108258 | W27: 11.213478 | X27: 12.318698 | Y27: 13.423918 | Z27: 13.669042 | AA27: 13.914166 | AB27: 14.159289 | AC27: 14.404413 | AD27: 14.808553 | AE27: 15.212694 | AF27: 15.616834 | AG27: 16.020974 | AH27: 17.47609 | AI27: 18.931205 | AJ27: 20.386321 | AK27: 21.841436 | AL27: 22.841443 | AM27: 23.84145 | AN27: 24.841457 | AO27: 25.841465 | AP27: 26.426995 | AQ27: 27.012525 | AR27: 27.598055 | AS27: 28.183586 | AT27: 28.768913 | AU27: 29.35424 | AV27: 29.939567 | AW27: 30.524894 | AX27: 32.896765 | AY27: 35.268637 | AZ27: 37.640508 | BA27: 40.012379 | BB27: 41.60339 | BC27: 43.1944 | BD27: 44.785411 | BE27: 46.376421 | BF27: 47.737141 | BG27: 49.09786 | BH27: 50.45858 | BI27: 51.8193 | BJ27: 53.804347 | BK27: 55.789395 | BL27: 57.774442 | BM27: 59.75949 | BN27: 60.09069 | BO27: 60.421891 | BP27: 60.753092 | BQ27: 61.084292 | BR27: 65.200366 | BS27: 69.316439 | BT27: 73.432513 | BU27: 77.548586 | BV27: 83.292941 | BW27: 89.037295 | BX27: 94.781649 | BY27: 100.526 | BZ27: 100.77234 | CA27: 101.01868 | CB27: 101.26502 | CC27: 101.51136 | CD27: 101.87355 | CE27: 102.23575 | CF27: 102.59794 | CG27: 102.96014 | CH27: 114.8857 | CI27: 126.81126 | CJ27: 138.73683 | CK27: 150.66239 | CL27: 165.80527 | CM27: 180.94816 | CN27: 196.09104 | CO27: 211.23392 | CP27: 212.29507 | CQ27: 213.35622 | CR27: 214.41738 | CS27: 215.47853 | CT27: 249.83406 | CU27: 284.18958 | CV27: 318.5451 | CW27: 352.90063
A28: BelowSmithsFork | B28: 56.001953 | C28: 56.377384 | D28: 56.752816 | E28: 57.128247 | F28: 57.226356 | G28: 57.324465 | H28: 57.422574 | I28: 57.520683 | J28: 59.791912 | K28: 62.063141 | L28: 64.33437 | M28: 66.605599 | N28: 66.653984 | O28: 66.702369 | P28: 66.750754 | Q28: 66.79914 | R28: 67.99236 | S28: 69.185581 | T28: 70.378802 | U28: 71.572022 | V28: 75.728192 | W28: 79.884362 | X28: 84.040532 | Y28: 88.196701 | Z28: 89.273817 | AA28: 90.350933 | AB28: 91.428049 | AC28: 92.505165 | AD28: 93.572218 | AE28: 94.63927 | AF28: 95.706322 | AG28: 96.773375 | AH28: 100.6608 | AI28: 104.54822 | AJ28: 108.43565 | AK28: 112.32307 | AL28: 116.0521 | AM28: 119.78113 | AN28: 123.51016 | AO28: 127.23919 | AP28: 129.50195 | AQ28: 131.7647 | AR28: 134.02745 | AS28: 136.2902 | AT28: 141.16238 | AU28: 146.03456 | AV28: 150.90675 | AW28: 155.77893 | AX28: 158.21792 | AY28: 160.65691 | AZ28: 163.0959 | BA28: 165.53489 | BB28: 167.19466 | BC28: 168.85443 | BD28: 170.5142 | BE28: 172.17398 | BF28: 172.46994 | BG28: 172.7659 | BH28: 173.06186 | BI28: 173.35783 | BJ28: 175.22333 | BK28: 177.08884 | BL28: 178.95435 | BM28: 180.81985 | BN28: 182.19402 | BO28: 183.56819 | BP28: 184.94236 | BQ28: 186.31653 | BR28: 190.00397 | BS28: 193.69141 | BT28: 197.37885 | BU28: 201.06628 | BV28: 209.76873 | BW28: 218.47118 | BX28: 227.17362 | BY28: 235.87607 | BZ28: 238.10045 | CA28: 240.32483 | CB28: 242.54921 | CC28: 244.77359 | CD28: 254.32719 | CE28: 263.88078 | CF28: 273.43438 | CG28: 282.98798 | CH28: 305.68342 | CI28: 328.37885 | CJ28: 351.07429 | CK28: 373.76972 | CL28: 376.50676 | CM28: 379.24379 | CN28: 381.98083 | CO28: 384.71786 | CP28: 406.45254 | CQ28: 428.18721 | CR28: 449.92188 | CS28: 471.65655 | CT28: 516.07278 | CU28: 560.489 | CV28: 604.90523 | CW28: 649.32145
A29: BelowWoodruff | B29: 35.984376 | C29: 38.880393 | D29: 41.776411 | E29: 44.672429 | F29: 46.667937 | G29: 48.663445 | H29: 50.658952 | I29: 52.65446 | J29: 53.372886 | K29: 54.091312 | L29: 54.809738 | M29: 55.528164 | N29: 57.116795 | O29: 58.705426 | P29: 60.294057 | Q29: 61.882688 | R29: 64.359058 | S29: 66.835429 | T29: 69.311799 | U29: 71.788169 | V29: 71.811073 | W29: 71.833977 | X29: 71.85688 | Y29: 71.879784 | Z29: 74.930084 | AA29: 77.980384 | AB29: 81.030685 | AC29: 84.080985 | AD29: 85.712468 | AE29: 87.343952 | AF29: 88.975435 | AG29: 90.606919 | AH29: 90.66044 | AI29: 90.713961 | AJ29: 90.767482 | AK29: 90.821003 | AL29: 91.614868 | AM29: 92.408732 | AN29: 93.202596 | AO29: 93.996461 | AP29: 94.07239 | AQ29: 94.148319 | AR29: 94.224248 | AS29: 94.300177 | AT29: 95.588334 | AU29: 96.876491 | AV29: 98.164647 | AW29: 99.452804 | AX29: 100.97803 | AY29: 102.50325 | AZ29: 104.02848 | BA29: 105.5537 | BB29: 106.64123 | BC29: 107.72876 | BD29: 108.81628 | BE29: 109.90381 | BF29: 112.17836 | BG29: 114.45291 | BH29: 116.72746 | BI29: 119.00201 | BJ29: 119.27621 | BK29: 119.55041 | BL29: 119.82461 | BM29: 120.09881 | BN29: 122.64602 | BO29: 125.19323 | BP29: 127.74045 | BQ29: 130.28766 | BR29: 130.40907 | BS29: 130.53048 | BT29: 130.65189 | BU29: 130.7733 | BV29: 132.01014 | BW29: 133.24699 | BX29: 134.48384 | BY29: 135.72068 | BZ29: 138.44602 | CA29: 141.17136 | CB29: 143.89669 | CC29: 146.62203 | CD29: 150.41318 | CE29: 154.20433 | CF29: 157.99548 | CG29: 161.78662 | CH29: 163.41382 | CI29: 165.04102 | CJ29: 166.66823 | CK29: 168.29543 | CL29: 170.32413 | CM29: 172.35284 | CN29: 174.38155 | CO29: 176.41026 | CP29: 182.7453 | CQ29: 189.08034 | CR29: 195.41538 | CS29: 201.75042 | CT29: 238.10387 | CU29: 274.45731 | CV29: 310.81076 | CW29: 347.16421
A30: BSFRIver | B30: 21.32427 | C30: 22.027918 | D30: 22.731565 | E30: 23.435213 | F30: 23.607139 | G30: 23.672721 | H30: 23.738303 | I30: 23.803884 | J30: 24.046223 | K30: 24.37694 | L30: 24.707656 | M30: 25.038373 | N30: 25.220365 | O30: 25.253632 | P30: 25.286899 | Q30: 25.320166 | R30: 25.429326 | S30: 25.690273 | T30: 25.95122 | U30: 26.212167 | V30: 26.445399 | W30: 26.54006 | X30: 26.63472 | Y30: 26.729381 | Z30: 26.824041 | AA30: 27.162325 | AB30: 27.500609 | AC30: 27.838893 | AD30: 28.177177 | AE30: 28.237127 | AF30: 28.24141 | AG30: 28.245693 | AH30: 28.249977 | AI30: 28.753341 | AJ30: 29.506247 | AK30: 30.259152 | AL30: 31.012058 | AM30: 31.83528 | AN30: 32.72882 | AO30: 33.62236 | AP30: 34.5159 | AQ30: 35.161993 | AR30: 35.313193 | AS30: 35.464392 | AT30: 35.615592 | AU30: 35.842162 | AV30: 36.445581 | AW30: 37.049 | AX30: 37.652419 | AY30: 38.255838 | AZ30: 38.375579 | BA30: 38.495321 | BB30: 38.615062 | BC30: 38.734804 | BD30: 39.200935 | BE30: 39.736345 | BF30: 40.271755 | BG30: 40.807166 | BH30: 41.120797 | BI30: 41.323539 | BJ30: 41.526281 | BK30: 41.729023 | BL30: 42.066926 | BM30: 42.53999 | BN30: 43.013055 | BO30: 43.486119 | BP30: 44.539663 | BQ30: 46.754167 | BR30: 48.96867 | BS30: 51.183173 | BT30: 53.332952 | BU30: 55.159104 | BV30: 56.985257 | BW30: 58.811409 | BX30: 60.637562 | BY30: 61.873193 | BZ30: 63.108824 | CA30: 64.344455 | CB30: 65.580086 | CC30: 66.176716 | CD30: 66.645544 | CE30: 67.114373 | CF30: 67.583202 | CG30: 69.245575 | CH30: 71.504719 | CI30: 73.763864 | CJ30: 76.023009 | CK30: 79.026778 | CL30: 82.775171 | CM30: 86.523565 | CN30: 90.271958 | CO30: 93.707006 | CP30: 96.515362 | CQ30: 99.323719 | CR30: 102.13208 | CS30: 106.01158 | CT30: 115.2468 | CU30: 124.48203 | CV30: 133.71726 | CW30: 142.95249
A31: Corrine | B31: 100.19564 | C31: 101.00311 | D31: 101.81059 | E31: 102.61807 | F31: 110.31439 | G31: 118.01071 | H31: 125.70703 | I31: 133.40335 | J31: 134.33759 | K31: 135.27183 | L31: 136.20607 | M31: 137.14031 | N31: 137.57747 | O31: 138.01462 | P31: 138.45177 | Q31: 138.88892 | R31: 145.32287 | S31: 151.75681 | T31: 158.19075 | U31: 164.62469 | V31: 166.52133 | W31: 168.41797 | X31: 170.31462 | Y31: 172.21126 | Z31: 172.62104 | AA31: 173.03083 | AB31: 173.44062 | AC31: 173.8504 | AD31: 177.7587 | AE31: 181.66699 | AF31: 185.57529 | AG31: 189.48358 | AH31: 193.6925 | AI31: 197.90142 | AJ31: 202.11033 | AK31: 206.31925 | AL31: 212.42094 | AM31: 218.52263 | AN31: 224.62432 | AO31: 230.72602 | AP31: 232.06444 | AQ31: 233.40287 | AR31: 234.74129 | AS31: 236.07972 | AT31: 242.07973 | AU31: 248.07974 | AV31: 254.07976 | AW31: 260.07977 | AX31: 264.03893 | AY31: 267.99809 | AZ31: 271.95725 | BA31: 275.9164 | BB31: 277.71851 | BC31: 279.52061 | BD31: 281.32271 | BE31: 283.12481 | BF31: 291.12324 | BG31: 299.12167 | BH31: 307.1201 | BI31: 315.11853 | BJ31: 328.09563 | BK31: 341.07273 | BL31: 354.04983 | BM31: 367.02693 | BN31: 405.88297 | BO31: 444.73901 | BP31: 483.59505 | BQ31: 522.4511 | BR31: 525.31906 | BS31: 528.18702 | BT31: 531.05498 | BU31: 533.92295 | BV31: 539.10844 | BW31: 544.29394 | BX31: 549.47943 | BY31: 554.66493 | BZ31: 580.64917 | CA31: 606.63341 | CB31: 632.61765 | CC31: 658.60189 | CD31: 689.37161 | CE31: 720.14132 | CF31: 750.91104 | CG31: 781.68075 | CH31: 814.5693 | CI31: 847.45785 | CJ31: 880.34641 | CK31: 913.23496 | CL31: 915.28042 | CM31: 917.32588 | CN31: 919.37135 | CO31: 921.41681 | CP31: 927.77977 | CQ31: 934.14272 | CR31: 940.50567 | CS31: 946.86862 | CT31: 1010.2458 | CU31: 1073.623 | CV31: 1137.0001 | CW31: 1200.3773
A32: Evanston | B32: 49.900113 | C32: 50.140552 | D32: 50.38099 | E32: 50.621429 | F32: 51.02611 | G32: 51.430791 | H32: 51.835471 | I32: 52.240152 | J32: 55.274241 | K32: 58.30833 | L32: 61.342419 | M32: 64.376509 | N32: 65.27223 | O32: 66.167951 | P32: 67.063672 | Q32: 67.959393 | R32: 68.393174 | S32: 68.826955 | T32: 69.260737 | U32: 69.694518 | V32: 71.029821 | W32: 72.365123 | X32: 73.700426 | Y32: 75.035729 | Z32: 75.085204 | AA32: 75.13468 | AB32: 75.184156 | AC32: 75.233632 | AD32: 75.570544 | AE32: 75.907455 | AF32: 76.244367 | AG32: 76.581279 | AH32: 78.223252 | AI32: 79.865226 | AJ32: 81.507199 | AK32: 83.149173 | AL32: 83.802671 | AM32: 84.456168 | AN32: 85.109666 | AO32: 85.763164 | AP32: 88.425539 | AQ32: 91.087915 | AR32: 93.750291 | AS32: 96.412667 | AT32: 97.487354 | AU32: 98.56204 | AV32: 99.636727 | AW32: 100.71141 | AX32: 105.67506 | AY32: 110.63871 | AZ32: 115.60236 | BA32: 120.566 | BB32: 120.72509 | BC32: 120.88418 | BD32: 121.04326 | BE32: 121.20235 | BF32: 123.81004 | BG32: 126.41774 | BH32: 129.02543 | BI32: 131.63313 | BJ32: 135.30614 | BK32: 138.97915 | BL32: 142.65216 | BM32: 146.32517 | BN32: 146.54707 | BO32: 146.76897 | BP32: 146.99087 | BQ32: 147.21276 | BR32: 149.13533 | BS32: 151.0579 | BT32: 152.98047 | BU32: 154.90304 | BV32: 157.00174 | BW32: 159.10045 | BX32: 161.19916 | BY32: 163.29787 | BZ32: 164.14838 | CA32: 164.99889 | CB32: 165.84939 | CC32: 166.6999 | CD32: 166.82077 | CE32: 166.94163 | CF32: 167.0625 | CG32: 167.18336 | CH32: 170.49185 | CI32: 173.80033 | CJ32: 177.10882 | CK32: 180.41731 | CL32: 180.74792 | CM32: 181.07854 | CN32: 181.40915 | CO32: 181.73977 | CP32: 185.01901 | CQ32: 188.29824 | CR32: 191.57748 | CS32: 194.85672 | CT32: 228.14435 | CU32: 261.43198 | CV32: 294.71961 | CW32: 328.00724
A33: ID-UT | B33: 144.79341 | C33: 154.60678 | D33: 164.42015 | E33: 174.23352 | F33: 181.8524 | G33: 189.47129 | H33: 197.09017 | I33: 204.70906 | J33: 207.29935 | K33: 209.88964 | L33: 212.47994 | M33: 215.07023 | N33: 215.10345 | O33: 215.13666 | P33: 215.16988 | Q33: 215.20309 | R33: 215.37313 | S33: 215.54318 | T33: 215.71322 | U33: 215.88326 | V33: 216.24764 | W33: 216.61201 | X33: 216.97639 | Y33: 217.34077 | Z33: 219.25188 | AA33: 221.163 | AB33: 223.07411 | AC33: 224.98523 | AD33: 225.01051 | AE33: 225.0358 | AF33: 225.06108 | AG33: 225.08636 | AH33: 226.51363 | AI33: 227.94089 | AJ33: 229.36816 | AK33: 230.79542 | AL33: 232.63019 | AM33: 234.46496 | AN33: 236.29973 | AO33: 238.1345 | AP33: 239.34562 | AQ33: 240.55674 | AR33: 241.76786 | AS33: 242.97897 | AT33: 246.50128 | AU33: 250.02358 | AV33: 253.54588 | AW33: 257.06819 | AX33: 257.41769 | AY33: 257.7672 | AZ33: 258.1167 | BA33: 258.4662 | BB33: 265.71209 | BC33: 272.95797 | BD33: 280.20385 | BE33: 287.44973 | BF33: 287.71694 | BG33: 287.98415 | BH33: 288.25136 | BI33: 288.51857 | BJ33: 289.1442 | BK33: 289.76984 | BL33: 290.39548 | BM33: 291.02111 | BN33: 294.53697 | BO33: 298.05283 | BP33: 301.56869 | BQ33: 305.08455 | BR33: 308.84134 | BS33: 312.59814 | BT33: 316.35493 | BU33: 320.11172 | BV33: 322.02933 | BW33: 323.94695 | BX33: 325.86456 | BY33: 327.78217 | BZ33: 330.9921 | CA33: 334.20203 | CB33: 337.41196 | CC33: 340.62189 | CD33: 342.04767 | CE33: 343.47345 | CF33: 344.89922 | CG33: 346.325 | CH33: 371.12539 | CI33: 395.92578 | CJ33: 420.72617 | CK33: 445.52656 | CL33: 455.25565 | CM33: 464.98475 | CN33: 474.71384 | CO33: 484.44293 | CP33: 499.308 | CQ33: 514.17306 | CR33: 529.03813 | CS33: 543.90319 | CT33: 544.35383 | CU33: 544.80446 | CV33: 545.2551 | CW33: 545.70574
A34: LBR | B34: 8.8230462 | C34: 9.6634267 | D34: 10.503807 | E34: 11.344188 | F34: 11.817198 | G34: 12.290208 | H34: 12.763218 | I34: 13.236228 | J34: 13.448979 | K34: 13.66173 | L34: 13.874481 | M34: 14.087232 | N34: 14.315674 | O34: 14.544115 | P34: 14.772557 | Q34: 15.000998 | R34: 15.083541 | S34: 15.166083 | T34: 15.248626 | U34: 15.331168 | V34: 15.45689 | W34: 15.582612 | X34: 15.708334 | Y34: 15.834057 | Z34: 16.096259 | AA34: 16.358461 | AB34: 16.620663 | AC34: 16.882865 | AD34: 16.963276 | AE34: 17.043687 | AF34: 17.124097 | AG34: 17.204508 | AH34: 17.692822 | AI34: 18.181135 | AJ34: 18.669449 | AK34: 19.157763 | AL34: 19.268117 | AM34: 19.378471 | AN34: 19.488825 | AO34: 19.599179 | AP34: 19.774426 | AQ34: 19.949674 | AR34: 20.124922 | AS34: 20.300169 | AT34: 21.212895 | AU34: 22.12562 | AV34: 23.038345 | AW34: 23.951071 | AX34: 25.108845 | AY34: 26.26662 | AZ34: 27.424394 | BA34: 28.582169 | BB34: 28.594067 | BC34: 28.605965 | BD34: 28.617863 | BE34: 28.629761 | BF34: 29.537776 | BG34: 30.445792 | BH34: 31.353808 | BI34: 32.261824 | BJ34: 34.536721 | BK34: 36.811619 | BL34: 39.086516 | BM34: 41.361414 | BN34: 44.840538 | BO34: 48.319662 | BP34: 51.798786 | BQ34: 55.27791 | BR34: 55.337895 | BS34: 55.397881 | BT34: 55.457867 | BU34: 55.517853 | BV34: 57.046746 | BW34: 58.575639 | BX34: 60.104532 | BY34: 61.633425 | BZ34: 61.726675 | CA34: 61.819926 | CB34: 61.913176 | CC34: 62.006427 | CD34: 62.057638 | CE34: 62.108849 | CF34: 62.16006 | CG34: 62.211271 | CH34: 64.401742 | CI34: 66.592214 | CJ34: 68.782685 | CK34: 70.973156 | CL34: 74.533583 | CM34: 78.09401 | CN34: 81.654437 | CO34: 85.214864 | CP34: 86.994309 | CQ34: 88.773754 | CR34: 90.553199 | CS34: 92.332644 | CT34: 97.49593 | CU34: 102.65922 | CV34: 107.8225 | CW34: 112.98579
A35: LoganRiver | B35: 40.652095 | C35: 44.555432 | D35: 48.458769 | E35: 52.362107 | F35: 53.775044 | G35: 55.187981 | H35: 56.600918 | I35: 58.013855 | J35: 59.104703 | K35: 60.195551 | L35: 61.2864 | M35: 62.377248 | N35: 63.193203 | O35: 64.009158 | P35: 64.825113 | Q35: 65.641068 | R35: 66.151244 | S35: 66.66142 | T35: 67.171597 | U35: 67.681773 | V35: 67.731695 | W35: 67.781617 | X35: 67.831539 | Y35: 67.881461 | Z35: 68.456184 | AA35: 69.030907 | AB35: 69.60563 | AC35: 70.180353 | AD35: 70.364921 | AE35: 70.549488 | AF35: 70.734056 | AG35: 70.918624 | AH35: 71.487348 | AI35: 72.056073 | AJ35: 72.624797 | AK35: 73.193522 | AL35: 74.059349 | AM35: 74.925176 | AN35: 75.791004 | AO35: 76.656831 | AP35: 78.760844 | AQ35: 80.864856 | AR35: 82.968869 | AS35: 85.072881 | AT35: 85.319517 | AU35: 85.566153 | AV35: 85.812788 | AW35: 86.059424 | AX35: 86.855251 | AY35: 87.651079 | AZ35: 88.446906 | BA35: 89.242734 | BB35: 89.681819 | BC35: 90.120905 | BD35: 90.559991 | BE35: 90.999077 | BF35: 92.747537 | BG35: 94.495998 | BH35: 96.244459 | BI35: 97.992919 | BJ35: 98.440631 | BK35: 98.888343 | BL35: 99.336055 | BM35: 99.783767 | BN35: 103.2849 | BO35: 106.78604 | BP35: 110.28717 | BQ35: 113.78831 | BR35: 119.0909 | BS35: 124.39349 | BT35: 129.69608 | BU35: 134.99867 | BV35: 136.94995 | BW35: 138.90122 | BX35: 140.85249 | BY35: 142.80376 | BZ35: 146.95418 | CA35: 151.1046 | CB35: 155.25502 | CC35: 159.40544 | CD35: 164.20628 | CE35: 169.00712 | CF35: 173.80797 | CG35: 178.60881 | CH35: 179.08642 | CI35: 179.56402 | CJ35: 180.04163 | CK35: 180.51923 | CL35: 181.61861 | CM35: 182.71798 | CN35: 183.81736 | CO35: 184.91673 | CP35: 191.58556 | CQ35: 198.25439 | CR35: 204.92322 | CS35: 211.59205 | CT35: 220.48729 | CU35: 229.38253 | CV35: 238.27778 | CW35: 247.17302
A36: Pescadero | B36: 130.60207 | C36: 138.95853 | D36: 147.31499 | E36: 155.67145 | F36: 160.3782 | G36: 165.08495 | H36: 169.7917 | I36: 174.49845 | J36: 176.28563 | K36: 178.07281 | L36: 179.85998 | M36: 181.64716 | N36: 190.41658 | O36: 199.186 | P36: 207.95543 | Q36: 216.72485 | R36: 217.66776 | S36: 218.61068 | T36: 219.5536 | U36: 220.49651 | V36: 220.76055 | W36: 221.02459 | X36: 221.28862 | Y36: 221.55266 | Z36: 221.84029 | AA36: 222.12793 | AB36: 222.41556 | AC36: 222.70319 | AD36: 226.10414 | AE36: 229.50508 | AF36: 232.90603 | AG36: 236.30697 | AH36: 236.98878 | AI36: 237.67058 | AJ36: 238.35239 | AK36: 239.03419 | AL36: 239.16477 | AM36: 239.29535 | AN36: 239.42593 | AO36: 239.55651 | AP36: 240.35854 | AQ36: 241.16056 | AR36: 241.96259 | AS36: 242.76461 | AT36: 243.37245 | AU36: 243.98029 | AV36: 244.58813 | AW36: 245.19597 | AX36: 248.65481 | AY36: 252.11366 | AZ36: 255.57251 | BA36: 259.03136 | BB36: 259.89991 | BC36: 260.76847 | BD36: 261.63702 | BE36: 262.50557 | BF36: 262.92845 | BG36: 263.35132 | BH36: 263.7742 | BI36: 264.19707 | BJ36: 264.63571 | BK36: 265.07435 | BL36: 265.51299 | BM36: 265.95163 | BN36: 266.11369 | BO36: 266.27575 | BP36: 266.43781 | BQ36: 266.59987 | BR36: 268.1254 | BS36: 269.65092 | BT36: 271.17644 | BU36: 272.70196 | BV36: 272.84499 | BW36: 272.98801 | BX36: 273.13103 | BY36: 273.27406 | BZ36: 274.97854 | CA36: 276.68303 | CB36: 278.38752 | CC36: 280.09201 | CD36: 280.56218 | CE36: 281.03235 | CF36: 281.50252 | CG36: 281.97269 | CH36: 282.42749 | CI36: 282.88229 | CJ36: 283.33709 | CK36: 283.79189 | CL36: 290.64395 | CM36: 297.49601 | CN36: 304.34806 | CO36: 311.20012 | CP36: 313.21088 | CQ36: 315.22165 | CR36: 317.23241 | CS36: 319.24317 | CT36: 339.72359 | CU36: 360.20402 | CV36: 380.68444 | CW36: 401.16487
... A57: WYBorder | B57: 24.049527 | C57: 25.707414 | D57: 27.365301 | E57: 29.023188 | F57: 29.719568 | G57: 30.415948 | H57: 31.112328 | I57: 31.808708 | J57: 32.664472 | K57: 33.520235 | L57: 34.375999 | M57: 35.231763 | N57: 35.240934 | O57: 35.250105 | P57: 35.259277 | Q57: 35.268448 | R57: 35.673129 | S57: 36.07781 | T57: 36.48249 | U57: 36.887171 | V57: 37.729153 | W57: 38.571135 | X57: 39.413117 | Y57: 40.255098 | Z57: 40.29808 | AA57: 40.341061 | AB57: 40.384043 | AC57: 40.427024 | AD57: 41.47271 | AE57: 42.518395 | AF57: 43.564081 | AG57: 44.609766 | AH57: 44.851692 | AI57: 45.093618 | AJ57: 45.335544 | AK57: 45.57747 | AL57: 45.863716 | AM57: 46.149962 | AN57: 46.436208 | AO57: 46.722454 | AP57: 47.473169 | AQ57: 48.223883 | AR57: 48.974597 | AS57: 49.725311 | AT57: 49.832939 | AU57: 49.940566 | AV57: 50.048193 | AW57: 50.155821 | AX57: 50.442513 | AY57: 50.729205 | AZ57: 51.015897 | BA57: 51.30259 | BB57: 51.65943 | BC57: 52.016271 | BD57: 52.373112 | BE57: 52.729953 | BF57: 52.852007 | BG57: 52.97406 | BH57: 53.096114 | BI57: 53.218168 | BJ57: 53.585419 | BK57: 53.952671 | BL57: 54.319922 | BM57: 54.687174 | BN57: 55.940926 | BO57: 57.194677 | BP57: 58.448429 | BQ57: 59.702181 | BR57: 59.74779 | BS57: 59.793399 | BT57: 59.839008 | BU57: 59.884617 | BV57: 62.50763 | BW57: 65.130644 | BX57: 67.753657 | BY57: 70.37667 | BZ57: 70.703865 | CA57: 71.03106 | CB57: 71.358255 | CC57: 71.68545 | CD57: 75.441748 | CE57: 79.198046 | CF57: 82.954343 | CG57: 86.710641 | CH57: 89.733229 | CI57: 92.755816 | CJ57: 95.778404 | CK57: 98.800992 | CL57: 99.105878 | CM57: 99.410764 | CN57: 99.715651 | CO57: 100.02054 | CP57: 102.51466 | CQ57: 105.00877 | CR57: 107.50289 | CS57: 109.99701 | CT57: 121.77162 | CU57: 133.54623 | CV57: 145.32083 | CW57: 157.09544
A61: Streamflow losses | B61: 0.3
A62: Effective Streamflow | B62: =1-B61 -> 0.7

Sheet BearLake_ElevationStorage

Sheet WaterAllocation
B1: Data Sources | C1: https://le.utah.gov/xcode/Title73/Chapter16/C73-16_1800010118000101.pdf
A3: Allocation - Storage
C4: UT | D4: ID | E4: WY
A5: Upper and Central Division | B5: Above Stwart Dam (pre compact) | C5: 11850 | D5: 324 | E5: 2150 | F5: =SUM(C5:E5) -> 14324
B6: Above Stewart Dam (compsct) | C6: 17750 | D6: 1000 | E6: 17750 | F6: =SUM(C6:E6) -> 36500
B7: Above Bear Lake (amended) | C7: 35000 | D7: 4500 | E7: 35000 | F7: =SUM(C7:E7) -> 74500
B8: Additioal Bear Lake Spillage | C8: 0.47 | D8: 0.06 | E8: 0.47 | F8: =SUM(C8:E8) -> 1
A9: Lower Division | B9: Tier 1 (ID first right) | C9: 275000 | D9: 125000
B10: Tier 2 (Next 75,000 acft) | C10: =0.5 -> 0.5 | D10: =0.5 -> 0.5
B11: Excess | C11: 0.3 | D11: 0.7
A13: Allocation Streamflow
C14: UT | D14: ID | E14: WY
A15: Upper Division | B15: Upper Utah Section. | C15: 0.6 | D15: 324 | E15: 2150
B16: Upper Wyoming Section | C16: 17750 | D16: 1000 | E16: 17750
B17: Lower Utah Section. | C17: 35000 | D17: 4500 | E17: 35000
B18: Lower Wyoming Section | C18: 0.47 | D18: 0.06 | E18: 0.47
A19: Lower Division | B19: Tier 1 (ID first right) | C19: 275000 | D19: 125000
B20: Tier 2 (Next 75,000 acft) | C20: =0.5 -> 0.5 | D20: =0.5 -> 0.5
B21: Excess | C21: 0.3 | D21: 0.7
A28: Storage Rights
C29: UT | D29: ID | E29: WY
A30: Upper & Central Division | B30: Above Stewart Dam (original) | C30: 11850 | D30: 324 | E30: 2150
B31: Above Stewart Dam (amended) | C31: 35000 | D31: 35000
A33: Lower Division

Sheet HistoricWaterUse
B1: https://idwr.idaho.gov/water-data/water-rights-accounting/wd11/

Sheet WaterBalance
F1: https://www.bearrivercommission.org/docs/Bear%20River%20Stream%20Flow%20and%20Depletions%20Schematic%20Map%201990.pdf
A2: Point | B2: Volume (1000 acft) | C2: Flow Type | D2: State | E2: Division
A3: Whitney Reservoir | B3: 33 | C3: Inflow | D3: UT | E3: Upper
A4: East Fork | B4: 39 | C4: Inflow | D4: UT | E4: Upper
A5: Hayden Fork | B5: 71 | C5: Inflow | D5: UT | E5: Upper
A6: UT - WY | B6: 140 | C6: Streamflow | D6: UT/WY | E6: Upper
A7: UT - WY | B7: 14 | C7: Depletion | D7: UT/WY | E7: Upper
A8: Mill Creek | B8: 26 | C8: Inflow | D8: WY | E8: Upper
A9: Mill Creek | B9: 5 | C9: Depletion | D9: WY | E9: Upper
A10: Mill Creek | B10: 21 | C10: Outflow | D10: WY | E10: Upper
A11: Sulphur Creek Reservoir | B11: 16 | C11: Inflow | D11: WY | E11: Upper
A12: Coyote Creek | B12: 1 | C12: Inflow | D12: WY | E12: Upper
A13: Yellow Creek | B13: 9 | C13: Inflow | D13: WY | E13: Upper
A14: Yellow Creek | B14: 8 | C14: Outflow | D14: WY | E14: Upper
... A22: Twin Creek | B22: 13 | C22: Inflow | D22: WY | E22: Upper
A23: Tributaries before Pixley | B23: =8+6 -> 14 | C23: Inflow | D23: WY | E23: Upper
A24: Pixley Dam | B24: 177 | C24: Diversion | D24: WY | E24: Upper
A25: Below Pixley Dam | B25: 10 | C25: Depletion | D25: WY | E25: Central
A26: Triibutary below Pixley | B26: 6 | C26: Inflow | D26: WY | E26: Central
A27: Below Pixley Dam | B27: =B24+B26-B25 -> 173 | C27: Streamflow | D27: WY | E27: Central
A28: Smiths Fork | B28: =136+36 -> 172 | C28: Inflow | D28: WY | E28: Central
A29: Smiths Fork | B29: 10 | C29: Depletion | D29: WY | E29: Central
A30: Smiths Fork | B30: =B28-B29 -> 162 | C30: Inflow to BR | D30: WY | E30: Central
A31: Cokeville | B31: =B27+B30 -> 335 | C31: Streamflow | D31: WY | E31: Central
A32: Below Cokeville | B32: 12 | C32: Inflow | D32: ID | E32: Central
A33: Below Cokeville | B33: 4 | C33: Depletion | D33: ID | E33: Central
A34: Thomas Fork | B34: =40+20 -> 60 | C34: Inflow | D34: ID | E34: Central
A35: Thomas Fork | B35: 10 | C35: Depletion | D35: ID | E35: Central
A36: Thomas Fork | B36: =B34-B35 -> 50 | C36: Inflow to BR | D36: ID | E36: Central
A37: Harer | B37: =B31+B36+B32-B33 -> 393 | C37: Streamflow | D37: ID | E37: Central
A38: Below Harer | B38: =21+44+11 -> 76 | C38: Depletion | D38: ID | E38: Central
A39: Stewart Dam | C39: Diversion | D39: ID | E39: Central
A40: Bear Lake | B40: 304 | C40: Depletion | D40: ID | E40: Lower
A41: Bear Lake | B41: 332 | C41: Inflow to BR | D41: ID | E41: Lower
A42: Trib below Bear Lake | B42: 109 | C42: Inflow | D42: ID | E42: Lower
A43: Montpelier Creek | B43: 12 | C43: Inflow | D43: ID | E43: Lower
A44: Pescadero | B44: 466 | C44: Inflow | D44: ID | E44: Lower
A45: Georgetown Creek | B45: 23 | C45: Inflow | D45: ID | E45: Lower
A46: Stauffer Cr. & Others | B46: 18 | C46: Inflow | D46: ID | E46: Lower
A47: Johnson Budge | B47: 2 | C47: Depletion | D47: ID | E47: Lower
...

Sheet Scenarios
A1: Water Emergency Scenarios and limits
A2: https://waterplan.state.wy.us/BAG/bear/briefbook/bcompact.html
A4: Divison | B4: Upper Division | C4: Central Divison | E4: Lower Division
A5: Point of measurement | B5: Pixley Dam | C5: Divertable flow | D5: Bear river entering ID | E5: Bear Lake
A6: Flow limmit (cfs) | B6: 1250 | C6: 870 | D6: 350
A7: Elevation limit (ft) | E7: 5911
A8: Allocation | E8: No diversion for storage above stewart dam
A9: Upper Utah Section | B9: 0.006
A10: Upper Wyoming Section | B10: 0.49
A11: Lower Utah Section | B11: 0.405
A12: Lower Wyoming Section | B12: 0.096
A13: Wyoming | C13: 0.43 | D13: 0.43
A14: Idaho | C14: 0.57 | D14: 0.57
A15: Utah

Sheet WaterAllocation-Summary
A2: Upper Division
A3: Central Division
A4: Lower Division
A6: Bear River Migratory Bird Refugee

Sheet Depeltions
A1: https://www.bearrivercommission.org/docs/BRC%202019%20Depletions%20Report%20(Final%20Adopted%202023-04-18)%20(w%20appendices).pdf
A3: Estimated Depletions (Acre feet) | C3: Changes from 1976 to 2019
C4: UT | D4: ID | E4: WY
A5: Upper & Central Division | B5: Limit - Above Stewart Dam | C5: 13000 | D5: 2000 | E5: 13000
B6: Agricultural Depletions | C6: 5839 | D6: 1150 | E6: 5058
B7: M & I Depletions | C7: -8 | D7: 3 | E7: 826
B8: Reservoir Evaporation | C8: 582 | D8: 0 | E8: 140
B9: Total Depletions | C9: =SUM(C6:C8) -> 6413 | D9: =SUM(D6:D8) -> 1153 | E9: =SUM(E6:E8) -> 6024
B10: Remaining Allocation | C10: =C5-C9 -> 6587 | D10: =D5-D9 -> 847 | E10: =E5-E9 -> 6976
A11: Lower Division | B11: Limit | C11: 275000 | D11: 125000
B12: Agricultural Depletions | C12: -16879 | D12: 16387
B13: M & I Depletions | C13: 11543 | D13: 245
B14: Reservoir Evaporation | C14: 0 | D14: 11
B15: Total Depletions | C15: =SUM(C12:C14) -> -5336 | D15: =SUM(D12:D14) -> 16643
B16: Remaining Allocation | C16: =IF(C11-C15 > C11,C11, C11-C15) -> 275000 | D16: =IF(D11-D15 > D11,D11, D11-D15) -> 108357

Sheet Add reports
A1: https://waterplan.state.wy.us/BAG/bear/briefbook/bcompact.html
A2: https://water.utah.gov/wp-content/uploads/2019/11/Bear-River-Development-Report-Volume-I-Report-Final.pdf
A3: https://api.mountainscholar.org/server/api/core/bitstreams/26890e0c-11de-42ca-a6bd-6b3a97ec1ba3/content

Sheet Sheet2
B1: https://water.utah.gov/wp-content/uploads/2024/02/Regional-Economic-Values-of-the-Bear-River.pdf
B4: ID | C4: UT | D4: WY
A5: Area (acres) | B5: 277657 | C5: 282782 | D5: 69293
