Workbook

Sheet Network
A1: Source | B1: http://www.bearriverbasin.org/rivers/rivers/

Sheet Model
A1: Bear River Basin Water Bank
B2: Partipants instructions are given bold blue text
A4: 1 | B4: Assign participants and define water use strategy. Cell C6 to D11
A5: User | C5: Person | D5: Strategy
A6: A | B6: UT, WY upstream Bear Lake
A7: B | B7: Lower ID
A8: E | B8: BRCC
A9: D | B9: Other UT Users
A10: G | B10: Bank
A12: 2 | B12: Reservoir Assumptions | C12: Bear Lake | D12: Cutler
B13: Active Storage (acre-feet) | C13: ='BearLake-ElevationStorage'!B2 -> 1421000 | D13: 26548
B14: Max elvation (feet) | C14: 5923.65
B15: Protect elevation (feet) | C15: 5902
B16: Evaporation (acft) | C16: 125000
A18: 3 | B18: Water Budget (acft) | C18: Year 1 | D18: Year 2 | E18: Year 3 | F18: Year 4
B19: Specify Bear Lake Level | C19: 5920
A20: 3A | B20: Beginning of the year storage (acft) | C20: =IF(C$19 ="","", _xlfn.XLOOKUP(C$19, 'BearLake-ElevationStorage'!$A$2:$A$1404,'BearLake-ElevationStorage'!$B$2:$B$1404)) -> 1164985 | D20: =IF(D$19 ="","", _xlfn.XLOOKUP(D$19, 'BearLake-ElevationStorage'!$A$2:$A$1404,'BearLake-ElevationStorage'!$B$2:$B$1404)) | E20: =IF(E$19 ="","", _xlfn.XLOOKUP(E$19, 'BearLake-ElevationStorage'!$A$2:$A$1404,'BearLake-ElevationStorage'!$B$2:$B$1404)) | F20: =IF(F$19 ="","", _xlfn.XLOOKUP(F$19, 'BearLake-ElevationStorage'!$A$2:$A$1404,'BearLake-ElevationStorage'!$B$2:$B$1404))
B21: Total Start Storage for the System (acft) | C21: =C20 -> 1164985 | D21: =D20 | E21: =E20 | F21: =F20
B22: Net Water Available (acft) | C22: =IF(C$20="","",(C21-$C$16)) -> 1039985 | D22: =IF(D$20="","",(D21-$C$16)) | E22: =IF(E$20="","",(E21-$C$16)) | F22: =IF(F$20="","",(F21-$C$16))
A24: 3B | B24: Select a water year based on historic flows | C24: 2016 | D24: 2010 | E24: 2020 | F24: 2020
B25: Winter Flow (October - March) - acft | C25: 2015
B26: UT, WY upstream Bear Lake | C26: {=IF(C$24=" ","", SUMPRODUCT((HistoricalSeasonalFlows!$C$36:$C$53=Model!$B26)*(HistoricalSeasonalFlows!$E$4:$T$4=Model!C$24)*(HistoricalSeasonalFlows!$E$36:$T$53)))*1000} -> 0 | D26: {=IF(D$24=" ","", SUMPRODUCT((HistoricalSeasonalFlows!$C$36:$C$53=Model!$B26)*(HistoricalSeasonalFlows!$E$4:$T$4=Model!D$24)*(HistoricalSeasonalFlows!$E$36:$T$53)))*1000} -> 0 | E26: {=IF(E$24=" ","", SUMPRODUCT((HistoricalSeasonalFlows!$C$36:$C$53=Model!$B26)*(HistoricalSeasonalFlows!$E$4:$T$4=Model!E$24)*(HistoricalSeasonalFlows!$E$36:$T$53)))*1000} -> 0 | F26: {=IF(F$24=" ","", SUMPRODUCT((HistoricalSeasonalFlows!$C$36:$C$53=Model!$B26)*(HistoricalSeasonalFlows!$E$4:$T$4=Model!F$24)*(HistoricalSeasonalFlows!$E$36:$T$53)))*1000} -> 0
B27: Lower ID | C27: {=IF(C$24=" ","", SUMPRODUCT((HistoricalSeasonalFlows!$C$36:$C$53=Model!$B27)*(HistoricalSeasonalFlows!$E$4:$T$4=Model!C$24)*(HistoricalSeasonalFlows!$E$36:$T$53)))*1000} -> 84411.352 | D27: {=IF(D$24=" ","", SUMPRODUCT((HistoricalSeasonalFlows!$C$36:$C$53=Model!$B27)*(HistoricalSeasonalFlows!$E$4:$T$4=Model!D$24)*(HistoricalSeasonalFlows!$E$36:$T$53)))*1000} -> 143659.82 | E27: {=IF(E$24=" ","", SUMPRODUCT((HistoricalSeasonalFlows!$C$36:$C$53=Model!$B27)*(HistoricalSeasonalFlows!$E$4:$T$4=Model!E$24)*(HistoricalSeasonalFlows!$E$36:$T$53)))*1000} -> 209249.93 | F27: {=IF(F$24=" ","", SUMPRODUCT((HistoricalSeasonalFlows!$C$36:$C$53=Model!$B27)*(HistoricalSeasonalFlows!$E$4:$T$4=Model!F$24)*(HistoricalSeasonalFlows!$E$36:$T$53)))*1000} -> 209249.93
B28: BRCC | C28: {=IF(C$24=" ","", SUMPRODUCT((HistoricalSeasonalFlows!$C$36:$C$53=Model!$B28)*(HistoricalSeasonalFlows!$E$4:$T$4=Model!C$24)*(HistoricalSeasonalFlows!$E$36:$T$53)))*1000} -> 0 | D28: {=IF(D$24=" ","", SUMPRODUCT((HistoricalSeasonalFlows!$C$36:$C$53=Model!$B28)*(HistoricalSeasonalFlows!$E$4:$T$4=Model!D$24)*(HistoricalSeasonalFlows!$E$36:$T$53)))*1000} -> 0 | E28: {=IF(E$24=" ","", SUMPRODUCT((HistoricalSeasonalFlows!$C$36:$C$53=Model!$B28)*(HistoricalSeasonalFlows!$E$4:$T$4=Model!E$24)*(HistoricalSeasonalFlows!$E$36:$T$53)))*1000} -> 0 | F28: {=IF(F$24=" ","", SUMPRODUCT((HistoricalSeasonalFlows!$C$36:$C$53=Model!$B28)*(HistoricalSeasonalFlows!$E$4:$T$4=Model!F$24)*(HistoricalSeasonalFlows!$E$36:$T$53)))*1000} -> 0
B29: Other UT Users | C29: {=IF(C$24=" ","", SUMPRODUCT((HistoricalSeasonalFlows!$C$36:$C$53=Model!$B29)*(HistoricalSeasonalFlows!$E$4:$T$4=Model!C$24)*(HistoricalSeasonalFlows!$E$36:$T$53)))*1000} -> 0 | D29: {=IF(D$24=" ","", SUMPRODUCT((HistoricalSeasonalFlows!$C$36:$C$53=Model!$B29)*(HistoricalSeasonalFlows!$E$4:$T$4=Model!D$24)*(HistoricalSeasonalFlows!$E$36:$T$53)))*1000} -> 0 | E29: {=IF(E$24=" ","", SUMPRODUCT((HistoricalSeasonalFlows!$C$36:$C$53=Model!$B29)*(HistoricalSeasonalFlows!$E$4:$T$4=Model!E$24)*(HistoricalSeasonalFlows!$E$36:$T$53)))*1000} -> 0 | F29: {=IF(F$24=" ","", SUMPRODUCT((HistoricalSeasonalFlows!$C$36:$C$53=Model!$B29)*(HistoricalSeasonalFlows!$E$4:$T$4=Model!F$24)*(HistoricalSeasonalFlows!$E$36:$T$53)))*1000} -> 0
B32: Summer Flow (April - September) - acft
B33: Upper and Central | C33: {=IF(C$24=" "," ",SUMPRODUCT((HistoricalSeasonalFlows!$C$5:$C$29=Model!$B33)*(HistoricalSeasonalFlows!$E$4:$T$4=Model!C$24)*(HistoricalSeasonalFlows!$E$5:$T$29)))*1000} -> 1047776.1 | D33: {=IF(D$24=" "," ",SUMPRODUCT((HistoricalSeasonalFlows!$C$5:$C$29=Model!$B33)*(HistoricalSeasonalFlows!$E$4:$T$4=Model!D$24)*(HistoricalSeasonalFlows!$E$5:$T$29)))*1000} -> 1046453.3 | E33: {=IF(E$24=" "," ",SUMPRODUCT((HistoricalSeasonalFlows!$C$5:$C$29=Model!$B33)*(HistoricalSeasonalFlows!$E$4:$T$4=Model!E$24)*(HistoricalSeasonalFlows!$E$5:$T$29)))*1000} -> 837048.37 | F33: {=IF(F$24=" "," ",SUMPRODUCT((HistoricalSeasonalFlows!$C$5:$C$29=Model!$B33)*(HistoricalSeasonalFlows!$E$4:$T$4=Model!F$24)*(HistoricalSeasonalFlows!$E$5:$T$29)))*1000} -> 837048.37
B34: Bear Lake | C34: {=IF(C$24=" "," ",SUMPRODUCT((HistoricalSeasonalFlows!$C$5:$C$29=Model!$B34)*(HistoricalSeasonalFlows!$E$4:$T$4=Model!C$24)*(HistoricalSeasonalFlows!$E$5:$T$29)))*1000} -> 373377.09 | D34: {=IF(D$24=" "," ",SUMPRODUCT((HistoricalSeasonalFlows!$C$5:$C$29=Model!$B34)*(HistoricalSeasonalFlows!$E$4:$T$4=Model!D$24)*(HistoricalSeasonalFlows!$E$5:$T$29)))*1000} -> 285385.43 | E34: {=IF(E$24=" "," ",SUMPRODUCT((HistoricalSeasonalFlows!$C$5:$C$29=Model!$B34)*(HistoricalSeasonalFlows!$E$4:$T$4=Model!E$24)*(HistoricalSeasonalFlows!$E$5:$T$29)))*1000} -> 332253.63 | F34: {=IF(F$24=" "," ",SUMPRODUCT((HistoricalSeasonalFlows!$C$5:$C$29=Model!$B34)*(HistoricalSeasonalFlows!$E$4:$T$4=Model!F$24)*(HistoricalSeasonalFlows!$E$5:$T$29)))*1000} -> 332253.63
B35: Lower ID | C35: {=IF(C$24=" "," ",SUMPRODUCT((HistoricalSeasonalFlows!$C$5:$C$29=Model!$B35)*(HistoricalSeasonalFlows!$E$4:$T$4=Model!C$24)*(HistoricalSeasonalFlows!$E$5:$T$29)))*1000} -> 283791.89 | D35: {=IF(D$24=" "," ",SUMPRODUCT((HistoricalSeasonalFlows!$C$5:$C$29=Model!$B35)*(HistoricalSeasonalFlows!$E$4:$T$4=Model!D$24)*(HistoricalSeasonalFlows!$E$5:$T$29)))*1000} -> 216724.85 | E35: {=IF(E$24=" "," ",SUMPRODUCT((HistoricalSeasonalFlows!$C$5:$C$29=Model!$B35)*(HistoricalSeasonalFlows!$E$4:$T$4=Model!E$24)*(HistoricalSeasonalFlows!$E$5:$T$29)))*1000} -> 264197.07 | F35: {=IF(F$24=" "," ",SUMPRODUCT((HistoricalSeasonalFlows!$C$5:$C$29=Model!$B35)*(HistoricalSeasonalFlows!$E$4:$T$4=Model!F$24)*(HistoricalSeasonalFlows!$E$5:$T$29)))*1000} -> 264197.07
B36: Lower UT | C36: {=IF(C$24=" "," ",SUMPRODUCT((HistoricalSeasonalFlows!$C$5:$C$29=Model!$B36)*(HistoricalSeasonalFlows!$E$4:$T$4=Model!C$24)*(HistoricalSeasonalFlows!$E$5:$T$29)))*1000} -> 305084.55 | D36: {=IF(D$24=" "," ",SUMPRODUCT((HistoricalSeasonalFlows!$C$5:$C$29=Model!$B36)*(HistoricalSeasonalFlows!$E$4:$T$4=Model!D$24)*(HistoricalSeasonalFlows!$E$5:$T$29)))*1000} -> 224985.23 | E36: {=IF(E$24=" "," ",SUMPRODUCT((HistoricalSeasonalFlows!$C$5:$C$29=Model!$B36)*(HistoricalSeasonalFlows!$E$4:$T$4=Model!E$24)*(HistoricalSeasonalFlows!$E$5:$T$29)))*1000} -> 287449.73 | F36: {=IF(F$24=" "," ",SUMPRODUCT((HistoricalSeasonalFlows!$C$5:$C$29=Model!$B36)*(HistoricalSeasonalFlows!$E$4:$T$4=Model!F$24)*(HistoricalSeasonalFlows!$E$5:$T$29)))*1000} -> 287449.73
A39: 3C | B39: Water Available per source of water | C39: Year 1 | D39: Year 2 | E39: Year 3 | F39: Year 4
B40: =B6 -> UT, WY upstream Bear Lake | D40: =D29 -> 0 | E40: =E29 -> 0 | F40: =F29 -> 0
B41: =B7 -> Lower ID | D41: =SUM(D26:D27) -> 143659.82 | E41: =SUM(E26:E27) -> 209249.93 | F41: =SUM(F26:F27) -> 209249.93
B42: =B9 -> Other UT Users | D42: =D28 -> 0 | E42: =E28 -> 0 | F42: =F28 -> 0
B43: =B8 -> BRCC | D43: 0 | E43: 0 | F43: 0
D44: 0 | E44: 0 | F44: 0
A46: 4 | B46: Participant Dashboard- Here the users decide if they want to involve in water trading with the bank
C47: Year 1 | D47: Year 2 | E47: Year 3 | F47: Year 4
C53: Year 1 | D53: Year 2 | E53: Year 3 | F53: Year 4
C59: Year 1 | D59: Year 2 | E59: Year 3 | F59: Year 4
...

Sheet Diversions

Sheet HistoricalSeasonalFlows
C1: https://maps.idwr.idaho.gov/agol/accounting/ | G1: =870*1.982 -> 1724.34
B3: User | C3: Division | D3: Gain/Loss | E3: WaterYear
A4: Summer | E4: 2009 | F4: =E4+1 -> 2010 | G4: =F4+1 -> 2011 | H4: =G4+1 -> 2012 | I4: =H4+1 -> 2013 | J4: =I4+1 -> 2014 | K4: =J4+1 -> 2015 | L4: =K4+1 -> 2016 | M4: =L4+1 -> 2017 | ... T4: =S4+1 -> 2024
A5: UT-WY | B5: UT, WY upstream Bear Lake | C5: Upper and Central | D5: Gain | E5: 137.43201 | F5: 113.34808 | G5: 245.30602 | H5: 67.835059 | I5: 87.145116 | J5: 115.50717 | K5: 85.127017 | L5: 123.01322 | M5: 174.67176 | N5: 90.475961 | O5: 161.73526 | P5: 104.30223 | Q5: 65.55679 | R5: 100.76357 | S5: 178.78669 | T5: 130.87245
A6: Evanston | B6: UT, WY upstream Bear Lake | C6: Upper and Central | E6: 166.6999 | F6: 147.21276 | G6: 328.00724 | H6: 52.240152 | I6: 75.035729 | J6: 121.20235 | K6: 83.149173 | L6: 131.63313 | M6: 181.73977 | N6: 76.581279 | O6: 163.29787 | P6: 96.412667 | Q6: 50.621429 | R6: 100.71141 | S6: 194.85672 | T6: 146.32517
B7: UT, WY upstream Bear Lake | C7: Upper and Central | D7: Gain | E7: =E6-E5 -> 29.26789 | F7: =F6-F5 -> 33.864683 | G7: =G6-G5 -> 82.701213 | H7: =H6-H5 -> -15.594907 | I7: =I6-I5 -> -12.109388 | J7: =J6-J5 -> 5.695176 | K7: =K6-K5 -> -1.9778442 | L7: =L6-L5 -> 8.6199027 | ... T7: =T6-T5 -> 15.452726
A8: AboveWoodruff | B8: UT, WY upstream Bear Lake | C8: Upper and Central | E8: 142.97484 | F8: 130.36688 | G8: 345.65574 | H8: 36.024328 | I8: 50.526443 | J8: 96.740477 | K8: 61.036799 | L8: 115.31042 | M8: 170.96782 | N8: 54.292894 | O8: 153.19339 | P8: 77.183397 | Q8: 34.021518 | R8: 81.899764 | S8: 217.33855 | T8: 134.49126
B9: UT, WY upstream Bear Lake | C9: Upper and Central | D9: Gain | E9: =E6-E8 -> 23.725068 | F9: =F6-F8 -> 16.845882 | G9: =G6-G8 -> -17.648502 | H9: =H6-H8 -> 16.215824 | I9: =I6-I8 -> 24.509285 | J9: =J6-J8 -> 24.461872 | K9: =K6-K8 -> 22.112374 | L9: =L6-L8 -> 16.322708 | ... T9: =T6-T8 -> 11.833909
A10: BelowWoodruff | B10: UT, WY upstream Bear Lake | C10: Upper and Central | E10: 146.62203 | F10: 135.72068 | G10: 347.16421 | H10: 84.080985 | I10: 55.528164 | J10: 94.300177 | K10: 71.879784 | L10: 120.09881 | M10: 176.41026 | N10: 90.606919 | O10: 130.28766 | P10: 105.5537 | Q10: 44.672429 | R10: 90.821003 | S10: 168.29543 | T10: 161.78662
A11: Randolf | B11: UT, WY upstream Bear Lake | C11: Upper and Central | D11: Gain | E11: 2.830673 | F11: 2.4674667 | G11: 21.833227 | H11: 4.6493815 | I11: 1.7730994 | J11: 3.4370942 | K11: 3.11448 | L11: 3.8872551 | M11: 17.162072 | N11: 5.0111005 | O11: 9.9657648 | P11: 5.6803828 | Q11: 1.5262358 | R11: 1.7826377 | S11: 12.260691 | T11: 6.5075516
A12: BelowPixley_Cokeville | B12: UT, WY upstream Bear Lake | C12: Upper and Central | D12: Gain | E12: 77.548586 | F12: 51.8193 | G12: 352.90063 | H12: 16.020974 | I12: 4.1822858 | J12: 21.841436 | K12: 13.423918 | L12: 61.084292 | M12: 211.23392 | N12: 30.524894 | O12: 102.96014 | P12: 46.376421 | Q12: 3.0416444 | R12: 14.404413 | S12: 215.47853 | T12: 101.51136 | U12: =AVERAGE(E12:T12) -> 82.772046
A13: SmithsFork | B13: UT, WY upstream Bear Lake | C13: Upper and Central | D13: Gain | E13: 132.95499 | F13: 83.120618 | G13: 182.89249 | H13: 71.854402 | I13: 64.711239 | J13: 122.66382 | K13: 104.59591 | L13: 100.04889 | M13: 194.44703 | N13: 99.367932 | O13: 104.15767 | P13: 91.333212 | Q13: 53.841623 | R13: 74.587372 | S13: 123.67019 | T13: 94.204795 | U13: =AVERAGE(E13:T13) -> 106.15326
A14: BelowSmithsFork | B14: UT, WY upstream Bear Lake | C14: Upper and Central | D14: Gain | E14: 244.77359 | F14: 173.35783 | G14: 649.32145 | H14: 92.505165 | I14: 71.572022 | J14: 165.53489 | K14: 127.23919 | L14: 186.31653 | M14: 471.65655 | N14: 136.2902 | O14: 235.87607 | P14: 155.77893 | Q14: 57.520683 | R14: 96.773375 | S14: 384.71786 | T14: 201.06628 | U14: =AVERAGE(E14:T14) -> 215.64379
B15: UT, WY upstream Bear Lake | D15: Gain | E15: =E14-E12-E13 -> 34.270008 | F15: =F14-F12-F13 -> 38.417908 | G15: =G14-G12-G13 -> 113.52834 | H15: =H14-H12-H13 -> 4.6297894 | I15: =I14-I12-I13 -> 2.6784976 | J15: =J14-J12-J13 -> 21.029636 | K15: =K14-K12-K13 -> 9.2193636 | L15: =L14-L12-L13 -> 25.183346 | ... T15: =T14-T12-T13 -> 5.350134
A16: WYBorder | B16: UT, WY upstream Bear Lake | C16: Upper and Central | E16: 239.25886 | F16: 158.32907 | G16: 667.53729 | H16: 78.958499 | I16: 57.428473 | J16: 148.76863 | K16: 114.19859 | L16: 181.44093 | M16: 451.97528 | N16: 127.49242 | O16: 220.81875 | P16: 143.08773 | Q16: 47.022482 | R16: 81.047986 | S16: 361.53263 | T16: 183.59962 | U16: =AVERAGE(E16:T16) -> 203.90608
D17: Loss | E17: =E16-E14 -> -5.514723 | F17: =F16-F14 -> -15.02876 | G17: =G16-G14 -> 18.215838 | H17: =H16-H14 -> -13.546666 | I17: =I16-I14 -> -14.143549 | J17: =J16-J14 -> -16.766265 | K17: =K16-K14 -> -13.040605 | L17: =L16-L14 -> -4.8756021 | U17: =AVERAGE(E17:T17) -> -8.0875416
A18: BearLakeInflow | B18: Lower ID | C18: Bear Lake | D18: Inflow | E18: 212.33964 | F18: 115.43043 | G18: 675.44351 | H18: 39.564816 | I18: 23.258607 | J18: 120.9749 | K18: 91.854543 | L18: 146.91849 | M18: 544.75786 | N18: 91.900152 | O18: 212.55975 | P18: 130.11058 | Q18: 10.791486 | R18: 41.748099 | S18: 369.20882 | T18: 161.92186 | U18: =AVERAGE(E18:T18) -> 186.79897
A19: BearLakeOutflow | B19: Lower ID | C19: Bear Lake | D19: Outflow | E19: 91.358793 | F19: 169.955 | G19: 176.8142 | H19: 233.53791 | I19: 237.3413 | J19: 196.48754 | K19: 182.94761 | L19: 226.4586 | M19: 154.12074 | N19: 232.83394 | O19: 174.5972 | P19: 202.14305 | Q19: 248.10305 | R19: 215.49761 | S19: 110.10409 | T19: 175.98134 | U19: =AVERAGE(E19:T19) -> 189.26762
A20: Pescadero | B20: Lower ID | C20: Lower ID | E20: 155.67145 | F20: 216.72485 | G20: 319.24317 | H20: 272.70196 | I20: 273.27406 | J20: 239.03419 | K20: 239.55651 | L20: 283.79189 | M20: 262.50557 | N20: 280.09201 | O20: 245.19597 | P20: 264.19707 | Q20: 265.95163 | R20: 266.59987 | S20: 222.70319 | T20: 259.03136
B21: Lower ID | D21: Gain | E21: =E20-E19 -> 64.312656 | F21: =F20-F19 -> 46.769848 | G21: =G20-G19 -> 142.42898 | H21: =H20-H19 -> 39.164052 | I21: =I20-I19 -> 35.932753 | J21: =J20-J19 -> 42.546653 | K21: =K20-K19 -> 56.608899 | L21: =L20-L19 -> 57.333289 | ... T21: =T20-T19 -> 83.050023
A22: SodaSpring | B22: Lower ID | E22: 219.2028 | F22: 260.00303 | G22: 351.50658 | H22: 311.88822 | I22: 302.0228 | J22: 278.17127 | K22: 303.19872 | L22: 340.80036 | M22: 373.15301 | N22: 332.94173 | O22: 311.48567 | P22: 302.22308 | Q22: 275.94238 | R22: 273.14837 | S22: 231.26936 | T22: 284.92141
B23: Lower ID | D23: Gain | E23: =E22-E20 -> 63.531351 | F23: =F22-F20 -> 43.278184 | G23: =G22-G20 -> 32.26341 | H23: =H22-H20 -> 39.186258 | I23: =I22-I20 -> 28.748741 | J23: =J22-J20 -> 39.137079 | K23: =K22-K20 -> 63.642207 | L23: =L22-L20 -> 57.008471 | ... T23: =T22-T20 -> 25.890052
A24: ID-UT | B24: Lower ID | C24: Lower UT | E24: 288.51857 | F24: 224.98523 | G24: 543.90319 | H24: 242.97897 | I24: 238.1345 | J24: 215.20309 | K24: 258.4662 | L24: 305.08455 | M24: 484.44293 | N24: 291.02111 | O24: 346.325 | P24: 287.44973 | Q24: 225.08636 | R24: 230.79542 | S24: 445.52656 | T24: 340.62189
B25: Lower ID | D25: Gain | E25: =E24-E20 -> 132.84712
A26: Corrine | C26: Lower | D26: Inflow | E26: 533.92295 | F26: 275.9164 | G26: 1200.3773 | H26: 189.48358 | I26: 164.62469 | J26: 206.31925 | K26: 236.07972 | L26: 367.02693 | M26: 921.41681 | N26: 283.12481 | O26: 554.66493 | P26: 315.11853 | Q26: 102.61807 | R26: 172.21126 | S26: 913.23496 | T26: 522.4511
A27: LBR | C27: Other Users | E27: 55.517853 | F27: 28.582169 | G27: 112.98579 | H27: 19.599179 | I27: 15.000998 | J27: 16.882865 | K27: 11.344188 | L27: 32.261824 | M27: 85.214864 | N27: 28.629761 | O27: 62.211271 | P27: 23.951071 | Q27: 7.9826657 | R27: 15.834057 | S27: 92.332644 | T27: 55.27791
A28: BSFRIver | C28: Other Users | E28: 53.028593 | F28: 31.38851 | G28: 142.95249 | H28: 35.111593 | I28: 25.203732 | J28: 38.255838 | K28: 23.825745 | L28: 40.985636 | M28: 104.47237 | N28: 38.754761 | O28: 65.786025 | P28: 41.830393 | Q28: 20.620622 | R28: 25.342343 | S28: 92.770887 | T28: 60.637562
A29: LoganRiver | C29: Other Users | E29: 134.99867 | F29: 85.072881 | G29: 247.17302 | H29: 67.681773 | I29: 52.362107 | J29: 89.242734 | K29: 70.180353 | L29: 97.992919 | M29: 211.59205 | N29: 86.059424 | O29: 113.78831 | P29: 90.999077 | Q29: 36.748758 | R29: 58.013855 | S29: 180.51923 | T29: 142.80376
A32: EastCanal
A33: WestCanal
A35: Winter | E35: 2009 | F35: =E35+1 -> 2010 | G35: =F35+1 -> 2011 | H35: =G35+1 -> 2012 | I35: =H35+1 -> 2013 | J35: =I35+1 -> 2014 | K35: =J35+1 -> 2015 | L35: =K35+1 -> 2016 | M35: =L35+1 -> 2017 | ... T35: =S35+1 -> 2024
A36: UT-WY | C36: Upper and Central | E36: 14.648421 | F36: 13.878025 | G36: 19.696544 | H36: 22.84535 | I36: 13.88913 | J36: 18.693543 | K36: 26.692965 | L36: 14.604795 | M36: 24.763902 | N36: 20.240481 | O36: 14.421764 | P36: 16.870174 | Q36: 11.747689 | R36: 19.073684 | S36: 15.382924 | T36: 19.736006
A37: Evanston | C37: Upper and Central | E37: 16.662951 | F37: 14.398761 | G37: 22.887191 | H37: 37.563969 | I37: 14.027742 | J37: 20.973199 | K37: 9.330015 | L37: 19.874617 | M37: 37.225867 | N37: 27.794323 | O37: 10.261628 | P37: 23.349032 | Q37: 9.784122 | R37: 21.348581 | S37: 13.83202 | T37: 31.568765
A38: AboveWoodruff | C38: Upper and Central | E38: 14.493152 | F38: 11.536103 | G38: 24.201067 | H38: 42.520477 | I38: 8.9118201 | J38: 17.298502 | K38: 33.645958 | L38: 14.586988 | M38: 44.305356 | N38: 30.194744 | O38: 10.354096 | P38: 22.975871 | Q38: 4.0055212 | R38: 13.566913 | S38: 12.42996 | T38: 28.882197
A39: BelowWoodruff | C39: Upper and Central | E39: 6.4265064 | F39: 5.0475282 | G39: 11.213865 | H39: 37.816008 | I39: 6.1370281 | J39: 4.8685426 | K39: 6.7182057 | L39: 4.1034219 | M39: 47.647722 | N39: 11.075452 | O39: 5.9071587 | P39: 9.3117714 | Q39: 7.0756811 | R39: 7.4529072 | S39: 6.6117186 | T39: 21.695011
A40: Randolf | C40: Upper and Central | E40: 2.099997 | F40: 1.9860935 | G40: 2.1197675 | H40: 8.3559654 | I40: 1.9558726 | J40: 1.4795758 | K40: 1.8701871 | L40: 1.6958616 | M40: 3.9992946 | N40: 6.6626817 | O40: 2.778064 | P40: 3.8288954 | Q40: 2.2571299 | R40: 0.77652297 | S40: 1.2634684 | T40: 4.5493391
A41: SmithsFork | C41: Upper and Central | E41: 25.806365 | F41: 26.242625 | G41: 26.688999 | H41: 30.691089 | I41: 22.50011 | J41: 19.397309 | K41: 31.809105 | L41: 23.101752 | M41: 36.072555 | N41: 29.968881 | O41: 27.0971 | P41: 25.180531 | Q41: 20.264079 | R41: 20.696769 | S41: 21.879431 | T41: 24.868208
A42: BelowPixley_Cokeville | C42: Upper and Central | E42: 1.4838789 | F42: 0.4547019 | G42: 1.6627455 | H42: 3.454386 | I42: 0.61574133 | J42: 3.1481513 | K42: 0.8873925 | L42: 2.2669656 | M42: 29.983357 | N42: 7.39659 | O42: 3.281865 | P42: 9.3585702 | Q42: 0.7350981
A43: BelowSmithsFork | C43: Upper and Central | E43: 58.536177 | F43: 55.343547 | G43: 54.82995 | H43: 107.91288 | I43: 47.518629 | J43: 47.654663 | K43: 71.971002 | L43: 54.590007 | M43: 164.35897 | N43: 98.868414 | O43: 51.752334 | P43: 71.986866 | Q43: 51.212165 | R43: 36.263518 | S43: 41.802631 | T43: 99.574362
A44: WYBorder | C44: Upper and Central | E44: 59.702181 | F44: 54.687174 | G44: 53.218168 | H44: 109.99701 | I44: 45.57747 | J44: 46.722454 | K44: 71.68545 | L44: 52.729953 | M44: 157.09544 | N44: 98.800992 | O44: 50.155821 | P44: 70.37667 | Q44: 49.725311 | R44: 40.427024 | S44: 40.255098 | T44: 100.02054
...

Sheet WoodruffNarrows
A1: Woodruff Narrows Reservoir Capacity Table
A2: Elevation | B2: Area | C2: Cumulative Capacity
B3: (acres) | C3: (acre-feet)
A4: 6397 | B4: 0 | C4: 0
A5: 6400 | B5: 8.8 | C5: 17.6
A6: 6404 | B6: 312 | C6: 980
A7: 6410 | B7: 417.4 | C7: 1600
A8: 6411.7 | B8: 512.9 | C8: 3135
A9: 6415 | B9: 714 | C9: 6195
A10: 6420 | B10: 906 | C10: 10245
A11: 6425 | B11: 1114 | C11: 15245
A12: 6430 | B12: 1380 | C12: 21530
A13: 6439.4 | B13: 1620 | C13: 28100
A14: 6445 | B14: 1796 | C14: 37700
A15: 6450 | B15: 2086 | C15: 47405
A16: 6454.5 | B16: 2312 | C16: 57300

Sheet InflowQuantiles - Seasonal
B24: Water year
A25: Summer | B25: 2005 | C25: =B25+1 -> 2006 | D25: =C25+1 -> 2007 | E25: =D25+1 -> 2008 | F25: =E25+1 -> 2009 | G25: =F25+1 -> 2010 | H25: =G25+1 -> 2011 | I25: =H25+1 -> 2012 | J25: =I25+1 -> 2013 | ... U25: =T25+1 -> 2024
A26: AboveWoodruff | B26: 137.23213 | C26: 100.88592 | D26: 63.238861 | E26: 126.84359 | F26: 142.97484 | G26: 130.36688 | H26: 345.65574 | I26: 36.024328 | J26: 50.526443 | K26: 96.740477 | L26: 61.036799 | M26: 115.31042 | N26: 170.96782 | O26: 54.292894 | P26: 153.19339 | Q26: 77.183397 | R26: 34.021518 | S26: 81.899764 | T26: 217.33855 | U26: 134.49126
A27: BearLakeInflow | B27: 1578.468 | C27: 3077.616 | D27: 2149.572 | E27: 12508.764 | F27: 18354.648 | G27: 11223.78 | H27: 12881.568 | I27: 5488.944 | J27: 11675.904 | K27: 20290.056 | L27: 19219.236 | M27: 31950.096 | N27: 32632.248 | O27: 19536.516 | P27: 24200.532 | Q27: 33385.788 | R27: 19179.576 | S27: 19250.964 | T27: 7257.78 | U27: 4307.076
A28: BelowPixley_Cokeville | B28: 100.526 | C28: 40.012379 | D28: 28.183586 | E28: 59.75949 | F28: 77.548586 | G28: 51.8193 | H28: 352.90063 | I28: 16.020974 | J28: 4.1822858 | K28: 21.841436 | L28: 13.423918 | M28: 61.084292 | N28: 211.23392 | O28: 30.524894 | P28: 102.96014 | Q28: 46.376421 | R28: 3.0416444 | S28: 14.404413 | T28: 215.47853 | U28: 101.51136
A29: BelowSmithsFork | B29: 282.98798 | C29: 172.17398 | D29: 88.196701 | E29: 180.81985 | F29: 244.77359 | G29: 173.35783 | H29: 649.32145 | I29: 92.505165 | J29: 71.572022 | K29: 165.53489 | L29: 127.23919 | M29: 186.31653 | N29: 471.65655 | O29: 136.2902 | P29: 235.87607 | Q29: 155.77893 | R29: 57.520683 | S29: 96.773375 | T29: 384.71786 | U29: 201.06628
A30: BelowWoodruff | B30: 130.7733 | C30: 99.452804 | D30: 93.996461 | E30: 119.00201 | F30: 146.62203 | G30: 135.72068 | H30: 347.16421 | I30: 84.080985 | J30: 55.528164 | K30: 94.300177 | L30: 71.879784 | M30: 120.09881 | N30: 176.41026 | O30: 90.606919 | P30: 130.28766 | Q30: 105.5537 | R30: 44.672429 | S30: 90.821003 | T30: 168.29543 | U30: 161.78662
A31: BSFRIver | B31: 67.739478 | C31: 77.152581 | D31: 28.251404 | E31: 43.801496 | F31: 53.028593 | G31: 31.38851 | H31: 142.95249 | I31: 35.111593 | J31: 25.203732 | K31: 38.255838 | L31: 23.825745 | M31: 40.985636 | N31: 104.47237 | O31: 38.754761 | P31: 65.786025 | Q31: 41.830393 | R31: 20.620622 | S31: 25.342343 | T31: 92.770887 | U31: 60.637562
A32: Corrine | B32: 781.68075 | C32: 658.60189 | D32: 138.88892 | E32: 260.07977 | F32: 533.92295 | G32: 275.9164 | H32: 1200.3773 | I32: 189.48358 | J32: 164.62469 | K32: 206.31925 | L32: 236.07972 | M32: 367.02693 | N32: 921.41681 | O32: 283.12481 | P32: 554.66493 | Q32: 315.11853 | R32: 102.61807 | S32: 172.21126 | T32: 913.23496 | U32: 522.4511
A33: Evanston
A34: ID-UT
A35: LBR
A36: LoganRiver
A37: Pescadero | B37: 181.64716 | C37: 174.49845 | D37: 242.76461 | E37: 221.55266 | F37: 155.67145 | G37: 216.72485 | H37: 319.24317 | I37: 272.70196 | J37: 273.27406 | K37: 239.03419 | L37: 239.55651 | M37: 283.79189 | N37: 262.50557 | O37: 280.09201 | P37: 245.19597 | Q37: 264.19707 | R37: 265.95163 | S37: 266.59987 | T37: 222.70319 | U37: 259.03136
A38: Randolf | B38: 5.3774597 | C38: 6.9615198 | D38: 2.2494359 | E38: 4.0761556 | F38: 2.830673 | G38: 2.4674667 | H38: 21.833227 | I38: 4.6493815 | J38: 1.7730994 | K38: 3.4370942 | L38: 3.11448 | M38: 3.8872551 | N38: 17.162072 | O38: 5.0111005 | P38: 9.9657648 | Q38: 5.6803828 | R38: 1.5262358 | S38: 1.7826377 | T38: 12.260691 | U38: 6.5075516
A39: SmithsFork | B39: 125.32976 | C39: 104.97129 | D39: 57.884762 | E39: 94.501451 | F39: 132.95499 | G39: 83.120618 | H39: 182.89249 | I39: 71.854402 | J39: 64.711239 | K39: 122.66382 | L39: 104.59591 | M39: 100.04889 | N39: 194.44703 | O39: 99.367932 | P39: 104.15767 | Q39: 91.333212 | R39: 53.841623 | S39: 74.587372 | T39: 123.67019 | U39: 94.204795
A40: UT-WY | B40: 148.07477 | C40: 121.50892 | D40: 82.054755 | E40: 123.47903 | F40: 137.43201 | G40: 113.34808 | H40: 245.30602 | I40: 67.835059 | J40: 87.145116 | K40: 115.50717 | L40: 85.127017 | M40: 123.01322 | N40: 174.67176 | O40: 90.475961 | P40: 161.73526 | Q40: 104.30223 | R40: 65.55679 | S40: 100.76357 | T40: 178.78669 | U40: 130.87245
A41: WYBorder | B41: 245.84837 | C41: 160.38326 | D41: 76.536463 | E41: 169.82809 | F41: 239.25886 | G41: 158.32907 | H41: 667.53729 | I41: 78.958499 | J41: 57.428473 | K41: 148.76863 | L41: 114.19859 | M41: 181.44093 | N41: 451.97528 | O41: 127.49242 | P41: 220.81875 | Q41: 143.08773 | R41: 47.022482 | S41: 81.047986 | T41: 361.53263 | U41: 183.59962
A43: Winter | B43: 2005 | C43: =B43+1 -> 2006 | D43: =C43+1 -> 2007 | E43: =D43+1 -> 2008 | F43: =E43+1 -> 2009 | G43: =F43+1 -> 2010 | H43: =G43+1 -> 2011 | I43: =H43+1 -> 2012 | J43: =I43+1 -> 2013 | ... U43: =T43+1 -> 2024
A44: AboveWoodruff | B44: 4.937718 | C44: 5.8699148 | D44: 6.8021116 | E44: 7.7343084 | F44: 8.6665052 | G44: 9.1137387 | H44: 9.3877711 | I44: 9.6618034 | J44: 9.9358358 | K44: 10.209868 | L44: 10.460476 | M44: 10.685058 | N44: 10.909639 | O44: 11.13422 | P44: 11.358801 | Q44: 11.571857 | R44: 11.74169 | S44: 11.911522 | T44: 12.081355 | U44: 12.251188
A45: BearLakeInflow | B45: 0.02301093 | C45: 0.045010531 | D45: 0.067010131 | E45: 0.089009731 | F45: 0.11100933 | G45: 0.16410515 | H45: 0.22830676 | I45: 0.29250836 | J45: 0.35670997 | K45: 0.42091158 | L45: 0.46919545 | M45: 0.49979294 | N45: 0.53039043 | O45: 0.56098792 | P45: 0.59158542 | Q45: 0.61797736 | R45: 0.62859851 | S45: 0.63921965 | T45: 0.6498408 | U45: 0.66046195
A46: BelowPixley_Cokeville | B46: 27.248209 | C46: 29.850702 | D46: 32.453195 | E46: 34.718086 | F46: 35.126168 | G46: 35.53425 | H46: 35.942331 | I46: 36.227943 | J46: 36.237996 | K46: 36.24805 | L46: 36.258104 | M46: 36.336262 | N46: 36.493875 | O46: 36.651488 | P46: 36.8091 | Q46: 37.658986 | R46: 38.941543 | S46: 40.2241 | T46: 41.506657 | U46: 41.993634
A47: BelowSmithsFork | B47: 3.0843669 | C47: 3.2658202 | D47: 3.4472734 | E47: 3.6209152 | F47: 3.7515941 | G47: 3.882273 | H47: 4.0129519 | I47: 4.1394871 | J47: 4.2566991 | K47: 4.373911 | L47: 4.491123 | M47: 4.5834253 | N47: 4.6466663 | O47: 4.7099074 | P47: 4.7731484 | Q47: 4.8088432 | R47: 4.8273216 | S47: 4.8458 | T47: 4.8642784 | U47: 4.8790208
A48: BelowWoodruff | B48: 4.0949446 | C48: 7.9777081 | D48: 11.860472 | E48: 15.743235 | F48: 16.29213 | G48: 16.841024 | H48: 17.389919 | I48: 17.938813 | J48: 18.151539 | K48: 18.364266 | L48: 18.576992 | M48: 18.789718 | N48: 18.89105 | O48: 18.992381 | P48: 19.093712 | Q48: 19.195043 | R48: 19.39607 | S48: 19.597097 | T48: 19.798123 | U48: 19.99915
A49: BSFRIver | B49: 192.77401 | C49: 222.41058 | D49: 252.04715 | E49: 277.73018 | F49: 281.66869 | G49: 285.60721 | H49: 289.54572 | I49: 292.98151 | J49: 295.28615 | K49: 297.59079 | L49: 299.89544 | M49: 302.19342 | N49: 304.48362 | O49: 306.77383 | P49: 309.06403 | Q49: 310.39828 | R49: 311.13504 | S49: 311.8718 | T49: 312.60857 | U49: 312.91105
A50: Corrine | B50: 6.9271762 | C50: 7.5952112 | D50: 8.2632463 | E50: 8.9312813 | F50: 9.1885974 | G50: 9.2268633 | H50: 9.2651293 | I50: 9.3033952 | J50: 9.3618025 | K50: 9.4662471 | L50: 9.5706917 | M50: 9.6751363 | N50: 9.7795809 | O50: 9.8891734 | P50: 9.9989999 | Q50: 10.108826 | R50: 10.218653 | S50: 10.658569 | T50: 11.310687 | U50: 11.962804
A51: Evanston | B51: 101.9475 | C51: 106.97389 | D51: 112.00028 | E51: 116.59635 | F51: 118.82572 | G51: 121.05509 | H51: 123.28446 | I51: 124.878 | J51: 125.04092 | K51: 125.20384 | L51: 125.36677 | M51: 126.44941 | N51: 128.60505 | O51: 130.76069 | P51: 132.91633 | Q51: 135.27883 | R51: 137.77063 | S51: 140.26243 | T51: 142.75423 | U51: 143.779
A52: ID-UT | B52: 8.9406569 | C52: 9.739909 | D52: 10.539161 | E52: 11.242008 | F52: 11.414624 | G52: 11.58724 | H52: 11.759856 | I52: 11.940373 | J52: 12.138665 | K52: 12.336957 | L52: 12.535249 | M52: 12.723452 | N52: 12.899883 | O52: 13.076314 | P52: 13.252746 | Q52: 13.331011 | R52: 13.347922 | S52: 13.364833 | T52: 13.381744 | U52: 13.395839
A53: LBR | B53: 24.740701 | C53: 24.812882 | D53: 24.885064 | E53: 25.041491 | F53: 25.661269 | G53: 26.281048 | H53: 26.900827 | I53: 27.347244 | J53: 27.403597 | K53: 27.459949 | L53: 27.516302 | M53: 27.769543 | N53: 28.252487 | O53: 28.735431 | P53: 29.218375 | Q53: 29.51609 | R53: 29.698039 | S53: 29.879987 | T53: 30.061935 | U53: 30.130654
A54: LoganRiver | B54: 16.810359 | C54: 16.974623 | D54: 17.138887 | E54: 17.300691 | F54: 17.448972 | G54: 17.597253 | H54: 17.745534 | I54: 17.934633 | J54: 18.215572 | K54: 18.496512 | L54: 18.777451 | M54: 18.975866 | N54: 19.078003 | O54: 19.180139 | P54: 19.282276 | Q54: 19.550032 | R54: 19.921301 | S54: 20.29257 | T54: 20.66384 | U54: 21.296389
A55: Pescadero | B55: 0.78917015 | C55: 0.80181732 | D55: 0.8144645 | E55: 0.84235936 | F55: 0.95411648 | G55: 1.0658736 | H55: 1.1776307 | I55: 1.2556784 | J55: 1.25788 | K55: 1.2600815 | L55: 1.262283 | M55: 1.2813392 | N55: 1.3200593 | O55: 1.3587794 | P55: 1.3974994 | Q55: 1.4231412 | R55: 1.440609 | S55: 1.4580769 | T55: 1.4755447 | U55: 1.5093367
... A58: UT-WY | B58: 24.049527 | C58: 25.707414 | D58: 27.365301 | E58: 29.023188 | F58: 29.719568 | G58: 30.415948 | H58: 31.112328 | I58: 31.808708 | J58: 32.664472 | K58: 33.520235 | L58: 34.375999 | M58: 35.231763 | N58: 35.240934 | O58: 35.250105 | P58: 35.259277 | Q58: 35.268448 | R58: 35.673129 | S58: 36.07781 | T58: 36.48249 | U58: 36.887171
A59: WYBorder
B62: 0.3
A63: Streamflow losses | B63: =1-B62 -> 0.7
A64: Effective Streamflow
A66: Site | B66: Season | C66: 2005 | D66: 2006 | E66: 2007 | F66: 2008 | G66: 2009 | H66: 2010 | I66: 2011 | J66: 2012 | K66: 2013 | L66: 2014 | M66: 2015 | N66: 2016 | O66: 2017 | P66: 2018 | Q66: 2019 | R66: 2020 | S66: 2021 | T66: 2022 | U66: 2023 | V66: 2024
A67: AboveWoodruff | B67: Summer
A68: AboveWoodruff | B68: Winter | C68: 21.59368 | D68: 17.516434 | E68: 30.89514 | F68: 12.778769 | G68: 14.493152 | H68: 11.536103 | I68: 24.201067 | J68: 42.520477 | K68: 8.9118201 | L68: 17.298502 | M68: 33.645958 | N68: 14.586988 | O68: 44.305356 | P68: 30.194744 | Q68: 10.354096 | R68: 22.975871 | S68: 4.0055212 | T68: 13.566913 | U68: 12.42996 | V68: 28.882197
A69: BearLakeInflow | B69: Summer
...

Sheet BearLake-ElevationStorage
A1: Elevation (ft) | B1: Storage (acft) | E1: https://le.utah.gov/interim/2018/pdf/00003056.pdf
A2: 5923.65 | B2: 1421000
A3: 5923.64 | B3: 1420298.4
A4: 5923.63 | B4: 1419596.8
A5: 5923.62 | B5: 1418895.2
A6: 5923.61 | B6: 1418193.6
A7: 5923.6 | B7: 1417492
A8: 5923.59 | B8: 1416790.4
A9: 5923.58 | B9: 1416088.8
A10: 5923.57 | B10: 1415387.3
A11: 5923.56 | B11: 1414685.7
A12: 5923.55 | B12: 1413984.1
A13: 5923.54 | B13: 1413282.5
... A1404: 5902 | B1404: 0

Sheet Culter_ElevationStorage
A1: Pool Elevation (ft) | B1: Storage (acre-feet)
A2: 4412 | B2: 35828 | E2: Operating Range
A3: 4411 | B3: 29815 | E3: 4407.5
A4: 4410 | B4: 23802 | E4: 4406.5
A5: 4409.99 | B5: 23733
A6: 4409.98 | B6: 23664
A7: 4409.97 | B7: 23595
A8: 4409.96 | B8: 23526
A9: 4409.95 | B9: 23458
A10: 4409.94 | B10: 23390
A11: 4409.93 | B11: 23322
A12: 4409.92 | B12: 23254
A13: 4409.91 | B13: 23186
A14: 4409.9 | B14: 23119
A15: 4409.89 | B15: 23052
A16: 4409.88 | B16: 22985
... A1104: 4399 | B1104: 4

Sheet BearLake-EndofWaterYear
A1: Bear Lake Historic Elevation | I1: Back to model
A2: Date | B2: Month | C2: Day | D2: wateryear | E2: Elevation | F2: Storage
A3: 43848 | B3: =MONTH(A3) -> 1 | C3: =DAY(A3) -> 18 | D3: 2020 | E3: 5918.05 | F3: 1029325
A4: 43849 | B4: =MONTH(A4) -> 1 | C4: =DAY(A4) -> 19 | D4: 2020 | E4: 5918.05 | F4: 1029325
A5: 43850 | B5: =MONTH(A5) -> 1 | C5: =DAY(A5) -> 20 | D5: 2020 | E5: 5918.05 | F5: 1029325
A6: 43851 | B6: =MONTH(A6) -> 1 | C6: =DAY(A6) -> 21 | D6: 2020 | E6: 5918.05 | F6: 1029325
A7: 43852 | B7: =MONTH(A7) -> 1 | C7: =DAY(A7) -> 22 | D7: 2020 | E7: 5918.05 | F7: 1029325
A8: 43853 | B8: =MONTH(A8) -> 1 | C8: =DAY(A8) -> 23 | D8: 2020 | E8: 5918.05 | F8: 1029325
A9: 43854 | B9: =MONTH(A9) -> 1 | C9: =DAY(A9) -> 24 | D9: 2020 | E9: 5918.06 | F9: 1030017
A10: 43855 | B10: =MONTH(A10) -> 1 | C10: =DAY(A10) -> 25 | D10: 2020 | E10: 5918.06 | F10: 1030017
A11: 43856 | B11: =MONTH(A11) -> 1 | C11: =DAY(A11) -> 26 | D11: 2020 | E11: 5918.07 | F11: 1030709
A12: 43857 | B12: =MONTH(A12) -> 1 | C12: =DAY(A12) -> 27 | D12: 2020 | E12: 5918.07 | F12: 1030709
A13: 43858 | B13: =MONTH(A13) -> 1 | C13: =DAY(A13) -> 28 | D13: 2020 | E13: 5918.07 | F13: 1030709
A14: 43859 | B14: =MONTH(A14) -> 1 | C14: =DAY(A14) -> 29 | D14: 2020 | E14: 5918.07 | F14: 1030709
... A290: 44135 | B290: =MONTH(A290) -> 10 | C290: =DAY(A290) -> 31 | D290: 2021 | E290: 5916.08 | F290: 894076
A291: 44136 | B291: =MONTH(A291) -> 11 | D291: 2021 | E291: 5916.08 | F291: 894076
A292: 44137 | B292: =MONTH(A292) -> 11 | D292: 2021 | E292: 5916.08 | F292: 894076
A293: 44138 | B293: =MONTH(A293) -> 11 | D293: 2021 | E293: 5916.08 | F293: 894076
A294: 44139 | B294: =MONTH(A294) -> 11 | D294: 2021 | E294: 5916.08 | F294: 894076
A295: 44140 | B295: =MONTH(A295) -> 11 | D295: 2021 | E295: 5916.08 | F295: 894076
A296: 44141 | B296: =MONTH(A296) -> 11 | D296: 2021 | E296: 5916.09 | F296: 894757
A297: 44142 | B297: =MONTH(A297) -> 11 | D297: 2021 | E297: 5916.09 | F297: 894757
A298: 44143 | B298: =MONTH(A298) -> 11 | D298: 2021 | E298: 5916.09 | F298: 894757
A299: 44144 | B299: =MONTH(A299) -> 11 | D299: 2021 | E299: 5916.1 | F299: 895437
A300: 44145 | B300: =MONTH(A300) -> 11 | D300: 2021 | E300: 5916.1 | F300: 895437
A301: 44146 | B301: =MONTH(A301) -> 11 | D301: 2021 | E301: 5916.1 | F301: 895437
A302: 44147 | B302: =MONTH(A302) -> 11 | D302: 2021 | E302: 5916.07 | F302: 893396
... A624: 44469 | B624: =MONTH(A624) -> 9 | D624: 2021 | E624: 5912.31 | F624: 642122
A625: 44470 | B625: =MONTH(A625) -> 10 | C625: =DAY(A625) -> 1 | D625: 2022 | E625: 5912.26 | F625: 638844
A626: 44471 | B626: =MONTH(A626) -> 10 | C626: =DAY(A626) -> 2 | D626: 2022 | E626: 5912.25 | F626: 638189
A627: 44472 | B627: =MONTH(A627) -> 10 | C627: =DAY(A627) -> 3 | D627: 2022 | E627: 5912.23 | F627: 636879
A628: 44473 | B628: =MONTH(A628) -> 10 | C628: =DAY(A628) -> 4 | D628: 2022 | E628: 5912.23 | F628: 636879
A629: 44474 | B629: =MONTH(A629) -> 10 | C629: =DAY(A629) -> 5 | D629: 2022 | E629: 5912.22 | F629: 636224
A630: 44475 | B630: =MONTH(A630) -> 10 | C630: =DAY(A630) -> 6 | D630: 2022 | E630: 5912.21 | F630: 635569
A631: 44476 | B631: =MONTH(A631) -> 10 | C631: =DAY(A631) -> 7 | D631: 2022 | E631: 5912.21 | F631: 635569
A632: 44477 | B632: =MONTH(A632) -> 10 | C632: =DAY(A632) -> 8 | D632: 2022 | E632: 5912.21 | F632: 635569
A633: 44478 | B633: =MONTH(A633) -> 10 | C633: =DAY(A633) -> 9 | D633: 2022 | E633: 5912.26 | F633: 638844
A634: 44479 | B634: =MONTH(A634) -> 10 | C634: =DAY(A634) -> 10 | D634: 2022 | E634: 5912.29 | F634: 640811
A635: 44480 | B635: =MONTH(A635) -> 10 | C635: =DAY(A635) -> 11 | D635: 2022 | E635: 5912.29 | F635: 640811
A636: 44481 | B636: =MONTH(A636) -> 10 | C636: =DAY(A636) -> 12 | D636: 2022 | E636: 5912.29 | F636: 640811
...

Sheet BearLake-Data
F1: https://bearrivercommission.org/docs/Amended%20and%20Restated%20Bear%20Lake%20Settlement%20Agreement.pdf
A2: Date | B2: wateryear | C2: Elevation | D2: Storage | F2: Elevation | G2: Storage
A3: 43848 | B3: 2020 | C3: 5918.05 | D3: 1029325 | F3: 5923.65 | G3: 1421000
A4: 43849 | B4: 2020 | C4: 5918.05 | D4: 1029325 | F4: 5914.7 | G4: 801000
A5: 43850 | B5: 2020 | C5: 5918.05 | D5: 1029325 | F5: 5914 | G5: 754000
A6: 43851 | B6: 2020 | C6: 5918.05 | D6: 1029325 | F6: 5913 | G6: 688000
A7: 43852 | B7: 2020 | C7: 5918.05 | D7: 1029325 | F7: 5912 | G7: 622000
A8: 43853 | B8: 2020 | C8: 5918.05 | D8: 1029325 | F8: 5911 | G8: 557000
A9: 43854 | B9: 2020 | C9: 5918.06 | D9: 1030017 | F9: 5910 | G9: 492000
A10: 43855 | B10: 2020 | C10: 5918.06 | D10: 1030017 | F10: 5909 | G10: 428000
A11: 43856 | B11: 2020 | C11: 5918.07 | D11: 1030709 | F11: 5908 | G11: 365000
A12: 43857 | B12: 2020 | C12: 5918.07 | D12: 1030709 | F12: 5907 | G12: 303000
A13: 43858 | B13: 2020 | C13: 5918.07 | D13: 1030709 | F13: 5906 | G13: 241000
A14: 43859 | B14: 2020 | C14: 5918.07 | D14: 1030709 | F14: 5905 | G14: 180000
... A17: 43862 | B17: 2020 | C17: 5918.07 | D17: 1030709 | F17: 5902 | G17: 0
A18: 43863 | B18: 2020 | C18: 5918.08 | D18: 1031401
A19: 43864 | B19: 2020 | C19: 5918.08 | D19: 1031401
A20: 43865 | B20: 2020 | C20: 5918.11 | D20: 1033478
A21: 43866 | B21: 2020 | C21: 5918.11 | D21: 1033478
A22: 43867 | B22: 2020 | C22: 5918.11 | D22: 1033478
A23: 43868 | B23: 2020 | C23: 5918.11 | D23: 1033478
A24: 43869 | B24: 2020 | C24: 5918.12 | D24: 1034171
A25: 43870 | B25: 2020 | C25: 5918.12 | D25: 1034171
A26: 43871 | B26: 2020 | C26: 5918.12 | D26: 1034171
A27: 43872 | B27: 2020 | C27: 5918.12 | D27: 1034171
A28: 43873 | B28: 2020 | C28: 5918.12 | D28: 1034171
A29: 43874 | B29: 2020 | C29: 5918.12 | D29: 1034171
... A2006: 45851 | B2006: 2025 | C2006: 5917.89 | D2006: 1018257

Sheet WaterAllocation
B1: Data Sources | C1: https://le.utah.gov/xcode/Title73/Chapter16/C73-16_1800010118000101.pdf
A3: Allocation - Storage
C4: UT | D4: ID | E4: WY
A5: Upper and Central Division | B5: Above Stwart Dam (pre compact) | C5: 11850 | D5: 324 | E5: 2150 | F5: =SUM(C5:E5) -> 14324
B6: Above Stewart Dam (compsct) | C6: 17750 | D6: 1000 | E6: 17750 | F6: =SUM(C6:E6) -> 36500
B7: Above Bear Lake (amended) | C7: 35000 | D7: 4500 | E7: 35000 | F7: =SUM(C7:E7) -> 74500
B8: Additioal Bear Lake Spillage | C8: 0.47 | D8: 0.06 | E8: 0.47 | F8: =SUM(C8:E8) -> 1
A9: Lower Division | B9: Tier 1 (ID first right) | C9: 275000 | D9: 125000
B10: Tier 2 (Next 75,000 acft) | C10: =0.5 -> 0.5 | D10: =0.5 -> 0.5
B11: Excess | C11: 0.3 | D11: 0.7
A13: Allocation Streamflow
C14: UT | D14: ID | E14: WY
A15: Upper Division | B15: Upper Utah Section. | D15: 324 | E15: 2150
B16: Upper Wyoming Section | C16: 17750 | D16: 1000 | E16: 17750
B17: Lower Utah Section. | C17: 35000 | D17: 4500 | E17: 35000
B18: Lower Wyoming Section | C18: 0.47 | D18: 0.06 | E18: 0.47
A19: Lower Division | B19: Tier 1 (ID first right) | C19: 275000 | D19: 125000
B20: Tier 2 (Next 75,000 acft) | C20: =0.5 -> 0.5 | D20: =0.5 -> 0.5
B21: Excess | C21: 0.3 | D21: 0.7
A24: Storage Rights
C25: UT | D25: ID | E25: WY
A26: Upper & Central Division | B26: Above Stewart Dam (original) | C26: 11850 | D26: 324 | E26: 2150
B27: Above Stewart Dam (amended) | C27: 35000 | D27: 35000
A29: Lower Division

Sheet WaterBalance
F1: https://www.bearrivercommission.org/docs/Bear%20River%20Stream%20Flow%20and%20Depletions%20Schematic%20Map%201990.pdf
A2: Point | B2: Volume (1000 acft) | C2: Flow Type | D2: State | E2: Division
A3: Whitney Reservoir | B3: 33 | C3: Inflow | D3: UT | E3: Upper
A4: East Fork | B4: 39 | C4: Inflow | D4: UT | E4: Upper
A5: Hayden Fork | B5: 71 | C5: Inflow | D5: UT | E5: Upper
A6: UT - WY | B6: 140 | C6: Streamflow | D6: UT/WY | E6: Upper
A7: UT - WY | B7: 14 | C7: Depletion | D7: UT/WY | E7: Upper
A8: Mill Creek | B8: 26 | C8: Inflow | D8: WY | E8: Upper
A9: Mill Creek | B9: 5 | C9: Depletion | D9: WY | E9: Upper
A10: Mill Creek | B10: 21 | C10: Outflow | D10: WY | E10: Upper
A11: Sulphur Creek Reservoir | B11: 16 | C11: Inflow | D11: WY | E11: Upper
A12: Coyote Creek | B12: 1 | C12: Inflow | D12: WY | E12: Upper
A13: Yellow Creek | B13: 9 | C13: Inflow | D13: WY | E13: Upper
A14: Yellow Creek | B14: 8 | C14: Outflow | D14: WY | E14: Upper
... A22: Twin Creek | B22: 13 | C22: Inflow | D22: WY | E22: Upper
A23: Tributaries before Pixley | B23: =8+6 -> 14 | C23: Inflow | D23: WY | E23: Upper
A24: Pixley Dam | B24: 177 | C24: Diversion | D24: WY | E24: Upper
A25: Below Pixley Dam | B25: 10 | C25: Depletion | D25: WY | E25: Central
A26: Triibutary below Pixley | B26: 6 | C26: Inflow | D26: WY | E26: Central
A27: Below Pixley Dam | B27: =B24+B26-B25 -> 173 | C27: Streamflow | D27: WY | E27: Central
A28: Smiths Fork | B28: =136+36 -> 172 | C28: Inflow | D28: WY | E28: Central
A29: Smiths Fork | B29: 10 | C29: Depletion | D29: WY | E29: Central
A30: Smiths Fork | B30: =B28-B29 -> 162 | C30: Inflow to BR | D30: WY | E30: Central
A31: Cokeville | B31: =B27+B30 -> 335 | C31: Streamflow | D31: WY | E31: Central
A32: Below Cokeville | B32: 12 | C32: Inflow | D32: ID | E32: Central
A33: Below Cokeville | B33: 4 | C33: Depletion | D33: ID | E33: Central
A34: Thomas Fork | B34: =40+20 -> 60 | C34: Inflow | D34: ID | E34: Central
A35: Thomas Fork | B35: 10 | C35: Depletion | D35: ID | E35: Central
A36: Thomas Fork | B36: =B34-B35 -> 50 | C36: Inflow to BR | D36: ID | E36: Central
A37: Harer | B37: =B31+B36+B32-B33 -> 393 | C37: Streamflow | D37: ID | E37: Central
A38: Below Harer | B38: =21+44+11 -> 76 | C38: Depletion | D38: ID | E38: Central
A39: Stewart Dam | C39: Diversion | D39: ID | E39: Central
A40: Bear Lake | B40: 304 | C40: Depletion | D40: ID | E40: Lower
A41: Bear Lake | B41: 332 | C41: Inflow to BR | D41: ID | E41: Lower
A42: Trib below Bear Lake | B42: 109 | C42: Inflow | D42: ID | E42: Lower
A43: Montpelier Creek | B43: 12 | C43: Inflow | D43: ID | E43: Lower
A44: Pescadero | B44: 466 | C44: Inflow | D44: ID | E44: Lower
A45: Georgetown Creek | B45: 23 | C45: Inflow | D45: ID | E45: Lower
A46: Stauffer Cr. & Others | B46: 18 | C46: Inflow | D46: ID | E46: Lower
A47: Johnson Budge | B47: 2 | C47: Depletion | D47: ID | E47: Lower
...

Sheet Scenarios
A1: Water Emergency Scenarios and limits
A2: https://waterplan.state.wy.us/BAG/bear/briefbook/bcompact.html
A4: Divison | B4: Upper Division | C4: Central Divison (either scenario) | E4: Lower Division
A5: Point of measurement | B5: Pixley Dam | C5: Divertable flow | D5: Bear river entering ID | E5: Bear Lake
A6: Flow limmit (cfs) | B6: 1250 | C6: 870 | D6: 350
A7: Flow-Acft | B7: =B6*1.983 -> 2478.75 | C7: =C6*1.983 -> 1725.21 | D7: =D6*1.983 -> 694.05
A8: Elevation limit (ft) | E8: 5911
A9: Allocation | E9: No diversion for storage above stewart dam
A10: Upper Utah Section | B10: 0.006
A11: Upper Wyoming Section | B11: 0.49
A12: Lower Utah Section | B12: 0.405
A13: Lower Wyoming Section | B13: 0.096
A14: Wyoming | C14: 0.43 | D14: 0.43
A15: Idaho | C15: 0.57 | D15: 0.57
A16: Utah

Sheet BearLakeAllocation
C1: https://ffsl.utah.gov/wp-content/uploads/Bear_Lake_CMP_Compressed.pdf
A2: Lake Elevation | B2: UT-Allocation
A3: 5923.65 | B3: 245000
A4: 5914.7 | B4: 245000
A5: 5904 | C5: Decrease Allocation
A6: 5902 | B6: 0 | C6: No allocation

Sheet Depletions
A1: https://www.bearrivercommission.org/docs/BRC%202019%20Depletions%20Report%20(Final%20Adopted%202023-04-18)%20(w%20appendices).pdf
A3: Estimated Depletions (Acre feet) | C3: Changes from 1976 to 2019
C4: UT | D4: ID | E4: WY
A5: Upper & Central Division | B5: Limit - Above Stewart Dam | C5: 13000 | D5: 2000 | E5: 13000
B6: Agricultural Depletions | C6: 5839 | D6: 1150 | E6: 5058
B7: M & I Depletions | C7: -8 | D7: 3 | E7: 826
B8: Reservoir Evaporation | C8: 582 | D8: 0 | E8: 140
B9: Total Depletions | C9: =SUM(C6:C8) -> 6413 | D9: =SUM(D6:D8) -> 1153 | E9: =SUM(E6:E8) -> 6024
B10: Remaining Allocation | C10: =C5-C9 -> 6587 | D10: =D5-D9 -> 847 | E10: =E5-E9 -> 6976
A11: Lower Division | B11: Limit | C11: 275000 | D11: 125000
B12: Agricultural Depletions | C12: -16879 | D12: 16387
B13: M & I Depletions | C13: 11543 | D13: 245
B14: Reservoir Evaporation | C14: 0 | D14: 11
B15: Total Depletions | C15: =SUM(C12:C14) -> -5336 | D15: =SUM(D12:D14) -> 16643
B16: Remaining Allocation | C16: =IF(C11-C15 > C11,C11, C11-C15) -> 275000 | D16: =IF(D11-D15 > D11,D11, D11-D15) -> 108357

Sheet Add reports
A1: https://waterplan.state.wy.us/BAG/bear/briefbook/bcompact.html
A2: https://water.utah.gov/wp-content/uploads/2019/11/Bear-River-Development-Report-Volume-I-Report-Final.pdf
A3: https://api.mountainscholar.org/server/api/core/bitstreams/26890e0c-11de-42ca-a6bd-6b3a97ec1ba3/content
A4: https://bearlakewatch.org/wp-content/uploads/2024/05/2009-Original-CMPfinal_low_res_.pdf

Sheet Sheet3

Sheet Sheet2
